Workbook

Sheet 0_History_Log
A1: รายละเอียดการควบคุมเอกสาร
A2: รหัสเอกสาร
A3: ชื่อเอกสาร | B3: Risk Assessment Form ,Risk Treatment Plan Form
A4: ระดับชั้นความลับ | B4: ภายใน
A5: เจ้าของเอกสาร | B5: คณะกรรมการ ISMS
A7: ประวัติการปรับปรุงข้อมูล
A8: ลำดับ | B8: วันที่บันทึกปรับปรุงข้อมูล | C8: รายละเอียด | D8: ผู้ดำเนินงาน | E8: ผู้บันทึกข้อมูล
A9: 1 | B9: 16 สค 2568 | C9: กำหนดเกณฑ์การประเมินความเสี่ยง | D9: คณะกรรมการ ISMS | E9: Wanlaya
A10: 2 | B10: 17 สค 2568 | C10: รวบรวมและสรุป ความเสี่ยงด้านความมั่นคงปลอดภัย | D10: คณะกรรมการ ISMS | E10: Wanlaya
A12: 3 | B12: 20 สค 2568 | C12: ดำเนินการจัดทำแผนลดความเสี่ยง | D12: คณะกรรมการ ISMS | E12: Wanlaya
A13: 4 | B13: 25 สค 2568 | C13: ติดตามการดำเนินการแผนลดความเสี่ยง | D13: คณะกรรมการ ISMS | E13: Wanlaya

Sheet 0. Asset Evaluation 
A2: QA1: เป็นทรัพย์สินที่เก็บข้อมูลสารสนเทศหรือประมวลผลข้อมูลสารสนเทศของบริษัทฯ
A3: QA2: เป็นทรัพย์สินที่เมื่อสูญหาย เสียหาย ถูกเปิดเผย ไม่พร้อมใช้งานหรือถูกเปลี่ยนแปลง จะส่งผลกระทบต่อความปลอดภัยและความเป็นส่วนตัวของผู้ป่วยหรือบุคลากร
A4: QB1: เป็นทรัพย์สินที่หน่วยงานมีหน้าที่โดยตรงที่ต้องจัดเก็บควบคุมดูแลบำรุงรักษา
A5: QB2: เป็นทรัพย์สินที่หน่วยงานมีส่วนร่วมรับผิดชอบและกรณีเกิดความเสียหายกับทรัพย์สินนั้น หน่วยงานไม่สามารถปฏิเสธความรับผิดชอบได้
A6: QB3: เป็นทรัพย์สินที่มีระเบียบหรือคำสั่งที่มาจากภายนอกและมีผลให้หน่วยงานต้องรับผิดชอบในการควบคุม จัดเก็บ ดูแลหรือทำลายทรัพย์สินนั้น
A7: QB4: เป็นทรัพย์สินที่มีประโยชน์ต่อหน่วยงาน ในด้านสร้างความสามารถในการดำเนินธุรกิจหรือสร้างความได้เปรียบต่อคู่แข่ง
A8: QB5: เป็นทรัพย์สินที่ต้องทำการควบคุมการรับรู้ การเข้าถึงหรือการเปิดเผย
A9: QB6: เป็นทรัพย์สินที่ต้องทำการควบคุมความพร้อมใช้งาน
A10: QB7: เป็นทรัพย์สินที่ต้องทำการควบคุมความถูกต้อง

Sheet 1_Impact_LikeliHood
A1: ผลกระทบ (Impact)
A2: 1. ผลกระทบด้านการเงิน (Financial) | B2: ระดับผลกระทบ | D2: คำอธิบาย
B3: 5 | C3: สูงมาก | D3: มูลค่าความเสียหายสูงกว่า 1,000,001 บาท
B4: 4 | C4: สูง | D4: มูลค่าความเสียหายระหว่าง 500,001 – 1,000,000 บาท
B5: 3 | C5: ปานกลาง | D5: มูลค่าความเสียหายระหว่าง 100,001 – 500,000 บาท
B6: 2 | C6: ต่ำ | D6: มูลค่าความเสียหายระหว่าง 50,001 – 100,000 บาท
B7: 1 | C7: ต่ำมาก | D7: มูลค่าความเสียหายไม่เกิน 50,000 บาท
A8: 2. ผลกระทบด้านการปฏิบัติการ (Operation) | B8: 5 | C8: สูงมาก | D8: สูญเสียเวลามากกว่า 4 ชม.เพื่อให้ระบบสารสนเทศทำงาน เข้าถึง หรือใช้งานได้ดังเดิม
B9: 4 | C9: สูง | D9: สูญเสียเวลาระหว่าง 1-4 ชม.เพื่อให้ระบบสารสนเทศทำงาน เข้าถึง หรือใช้งานได้ดังเดิม
B10: 3 | C10: ปานกลาง | D10: สูญเสียเวลาระหว่าง 30 นาที – 1 ชม. เพื่อให้ระบบสารสนเทศทำงาน เข้าถึง หรือใช้งานได้ดังเดิม
B11: 2 | C11: ต่ำ | D11: สูญเสียเวลาระหว่าง 15-30 นาที เพื่อให้ระบบสารสนเทศทำงาน เข้าถึง หรือใช้งานได้ดังเดิม
B12: 1 | C12: ต่ำมาก | D12: สูญเสียเวลาน้อยกว่า 15 นาที เพื่อให้ระบบสารสนเทศทำงาน เข้าถึง หรือใช้งานได้ดังเดิม
A13: 3. ผลกระทบด้านภาพลักษณ์ (Reputation) | B13: 5 | C13: สูงมาก | D13: มีผลกระทบต่อภาพลักษณ์/ความเชื่อมั่นขององค์กรในระดับประเทศ และมีการเผยแพร่ข่าวผ่านสื่อภายในประเทศและต่างประเทศ
B14: 4 | C14: สูง | D14: มีผลกระทบต่อภาพลักษณ์องค์กร และมีการเผยแพร่ข่าวผ่านสื่อภายในประเทศ
B15: 3 | C15: ปานกลาง | D15: มีผลกระทบต่อภาพลักษณ์องค์กร แต่สามารถควบคุมได้
B16: 2 | C16: ต่ำ | D16: ไม่มี/มีผลกระทบเล็กน้อยต่อภาพลักษณ์องค์กร
B17: 1 | C17: ต่ำมาก | D17: ไม่เป็นที่สนใจต่อสื่อ และไม่มีผลทางกฎหมายหรือกฎระเบียบ
A18: 4. ผลกระทบด้านลูกค้า (Customer) | B18: 5 | C18: สูงมาก | D18: ผู้รับบริการ/ลูกค้า ไม่พอใจในการบริการ และ/หรือมีการร้องเรียนการดำเนินการงานของบริษัท
B19: 4 | C19: สูง | D19: ผู้รับบริการ/ลูกค้า ไม่พอใจและไม่กลับมาใช้บริการซ้ำ
B20: 3 | C20: ปานกลาง | D20: ผู้รับบริการ/ลูกค้า แสดงงความคิดเห็นในเชิงลบต่อการบริการ
B21: 2 | C21: ต่ำ | D21: ผู้รับบริการ/ลูกค้าไม่เข้าใจและพึ่งพอใจในการให้บริการ
B22: 1 | C22: ต่ำมาก | D22: ผู้รับบริการ/ลูกค้าไม่ได้รับบริการการอำนวยความสะดวกภายใน
A23: 5. ผลกระทบด้านพนักงาน (Employee) | B23: 5 | C23: สูงมาก | D23: ทุพลภาพหรือเสียชีวิต / เกิดการนัดหยุดงาน
B24: 4 | C24: สูง | D24: บาดเจ็บรุนแรงหรือเจ็บป่วยรุนแรง / เกิดการประท้วง
B25: 3 | C25: ปานกลาง | D25: บาดเจ็บต้องได้รับการรักษาทางการแพทย์ / ทำให้เกิดการเสียขวัญ กำลังใจในการปฏิบัติงาน หรือเกิดความไม่พึ่งพอใจ มากกว่า 1 หน่วยงาน
B26: 2 | C26: ต่ำ | D26: บาดเจ็บเล็กน้อย / ทำให้เกิดการเสียขวัญ กำลังใจในการปฏิบัติงาน หรือเกิดความไม่พึงพอใจเพียง 1 หน่วยงาน
B27: 1 | C27: ต่ำมาก | D27: ไม่มีผู้ได้รับบาดเจ็บ / ทำให้เกิดการเสียขวัญ กำลังใจในการปฏิบัติงาน หรือเกิดความไม่พึงพอใจในระดับบุคคล
A28: ความน่าจะเป็นหรือโอกาสเกิดความเสี่ยง (LikeliHood)
B29: โอกาสที่จะเกิด | D29: ความถี่ / ความน่าจะเป็นในการเกิดเหตุการณ์
B30: 5 | C30: สูงมาก | D30: 1 เดือนต่อครั้งหรือมากกว่า / มีโอกาสเกิดขึ้นเกือบทุกครั้ง
B31: 4 | C31: สูง | D31: 1-6 เดือนต่อครั้งแต่ไม่เกิน 5 ครั้ง / มีโอกาสในการเกิดค่อนข้างสูงหรือบ่อยๆ
B32: 3 | C32: ปานกลาง | D32: 1 ปีต่อครั้ง / มีโอกาสเกิดบางครั้ง
B33: 2 | C33: ต่ำ | D33: 2-4 ปีต่อครั้ง / อาจมีโอกาสเกิดแต่นานๆครั้ง
B34: 1 | C34: ต่ำมาก | D34: 5 ปีต่อครั้ง / แทบไม่มีโอกาสเกิด หรือ มีโอกาสเกิดในกรณียกเว้น

Sheet 2_Risk_Criteria
D2: การจัดระดับความเสี่ยง (Risk Degree)
C4: Risk Matrix | D4: Impact
C5: สูงมาก | D5: 5 | E5: M5 | F5: M10 | G5: H15 | H5: H20 | I5: C25 | J5: Likelihood
C6: สูง | D6: 4 | E6: L4 | F6: M8 | G6: H12 | H6: H16 | I6: C20
C7: ปานกลาง | D7: 3 | E7: L3 | F7: M6 | G7: M9 | H7: H12 | I7: H15
C8: ต่ำ | D8: 2 | E8: L2 | F8: L4 | G8: M6 | H8: M8 | I8: M10
C9: ตำ่มาก | D9: 1 | E9: L1 | F9: L2 | G9: L3 | H9: L4 | I9: M5
E10: 1 | F10: 2 | G10: 3 | H10: 4 | I10: 5
E11: ตำ่มาก | F11: ต่ำ | G11: ปานกลาง | H11: สูง | I11: สูงมาก
D13: ระดับของความเสี่ยง (Degree of Risk) | H13: การตอบสนองความเสี่ยง (Risk Response)
D14: Avoid | E14: ความเสี่ยงสูงมาก | H14: Avoid | I14: 4 | J14: Avoid | K14: Transfer | L14: Control
D15: Transfer | E15: ความเสี่ยงสูง | H15: Transfer | I15: 3 | J15: Transfer | K15: Control
D16: Control | E16: ความเสี่ยงปานกลาง | H16: Control | I16: 2 | J16: Control
D17: Accept | E17: ความเสี่ยงต่ำ | H17: Accept | I17: 1 | J17: Accept
I27: Degree | J27: Responsed
D28: ค่าคะแนน | E28: ระดับความเสี่ยง | F28: การจัดการที่แนะนำ | I28: L1 | J28: =$H$17 -> Accept
D29: 1–4 | E29: Low | F29: ยอมรับความเสี่ยงได้ (Accept) | I29: L2 | J29: =$H$17 -> Accept
D30: 5–9 | E30: Medium | F30: ประเมินควบคุมเพิ่มเติมหากคุ้มค่า | I30: L3 | J30: =$H$17 -> Accept
D31: 10–14 | E31: High | F31: ควรวางแผนควบคุมและเฝ้าระวังอย่างใกล้ชิด | I31: L4 | J31: =$H$17 -> Accept
D32: 15–19 | E32: Very High | F32: ควบคุมทันที / มีแผนรองรับฉุกเฉิน | I32: M5 | J32: =$H$16 -> Control
D33: 20–25 | E33: Critical | F33: ต้องควบคุมอย่างเร่งด่วน / ไม่สามารถยอมรับได้ | I33: M6 | J33: =$H$16 -> Control
I34: M8 | J34: =$H$16 -> Control
I35: M9 | J35: =$H$16 -> Control
I36: M10 | J36: =$H$16 -> Control
I37: H12 | J37: =$H$15 -> Transfer
I38: H15 | J38: =$H$15 -> Transfer
I39: H16 | J39: =$H$15 -> Transfer
I40: H20 | J40: =$H$15 -> Transfer
I41: C20 | J41: =$H$14 -> Avoid
I42: C25 | J42: =$H$14 -> Avoid

Sheet 3_Risk_Assessment
A1: ลำดับ (No.) | B1: กลุ่มของทรัพย์สิน (Group of asset) | C1: ประเภททรัพย์สิน (Type) | D1: C I A C : ความลับ I : ความถูกต้อง A : ความพร้อมใช้ | E1: เหตุการณ์ความเสี่ยง (Risk Scenario) | F1: มาตรการที่ใช้ในปัจจุบัน (Existing Control) | G1: ความเสี่ยงปัจจุบัน (Current Risk) | N1: ระดับความเสี่ยง (Risk level) | O1: ทางเลือกการตอบสนองต่อความเสี่ยง (Risk Response Option) | P1: มาตรการควบคุมที่เลือก (Selected control) | Q1: แนวทางการตอบสนองต่อความเสี่ยง (Risk Response Solution) | R1: หมายเลขแผน | S1: ความเสี่ยงที่คาดว่าจะเหลือ (Residual Risk) | Z1: สูตรค้นหาความเสี่ยง | AA1: ผู้รับผิดชอบความเสี่ยง (Risk Owner)
G2: ผลกระทบ (Impact) | L2: ระดับผลกระทบสูงสุด | M2: โอกาสเกิด (Likelihood) | S2: ผลกระทบ (Impact) | X2: ระดับผลกระทบสูงสุด | Y2: โอกาสเกิด (Likelihood)
G3: F | H3: O | I3: R | J3: C | K3: E | S3: F | T3: O | U3: R | V3: C | W3: E
A4: 1 | B4: Hardware | C4: Hardware | D4: C,I,A | E4: เครื่องNotebook ติดไวรัส ทำให้ข้อมูลรั่วไหล ข้อมูลถูกทำลาย และใช้งานโปรแกรม ไม่ได้ | F4: 1. ติดตั้ง Virus / แก้ไข 2. นำเครื่องสำรองมาใช้ | G4: 2 | H4: 1 | I4: 1 | J4: 1 | K4: 4 | L4: =IFERROR(MAX(G4:K4),"") -> 4 | M4: 1 | N4: =IF(ISBLANK(L4),"",VLOOKUP(L4,'2_Risk_Criteria'!$D$4:$I$9,M4+1,0)) -> L4 | O4: =VLOOKUP(N4,'2_Risk_Criteria'!$I$28:$J$42,2,0) -> Accept | P4: 1.มีการตรวจสอบการ Update Virus โดยผู้บังคับบัญชา 2.นำ Event Log มาทบทวนและวิเคราะห์หาสาเหตุสัปดาห์ละ 1 ครั้ง | S4: 1 | T4: 1 | U4: 1 | V4: 1 | W4: 1 | X4: =IFERROR(MAX(S4:W4),"") -> 1 | Y4: 1 | Z4: =IF(OR(ISBLANK(L4),ISBLANK(l)),"",VLOOKUP(X4-0,'2_Risk_Criteria'!$D$4:$I$9,Y4+1,0)) -> L1
A5: 2 | B5: Hardware | C5: Hardware | D5: A | E5: เครื่องNotebook ถูกขโมย เนื่องจากไม่มีการควบคุมการเข้า - ออกพื้นที่ | F5: 1.CCTV 2.มีเครื่องสำรองทดแทน 3.แจ้งความ | G5: 1 | H5: 3 | I5: 2 | J5: 3 | K5: 2 | L5: =IFERROR(MAX(G5:K5),"") -> 3 | M5: 1 | N5: =IF(ISBLANK(L5),"",VLOOKUP(L5,'2_Risk_Criteria'!$D$4:$I$9,M5+1,0)) -> L3 | O5: =VLOOKUP(N5,'2_Risk_Criteria'!$I$28:$J$42,2,0) -> Accept | P5: 1.จัดทำทะเบียนทรัพย์สินสารสนเทศ 2.จัดทำนโยบายสำรวจทรัพย์สินปีละ 1 ครั้ง 3.วางแผนการบริหารจัดการเครื่องสำรองให้เพียงพอ 4.จัดหาโปรแกรมบริหารจัดการทรัพย์สิน เพื่อตรวจสอบทรัพย์สิน | S5: 1 | T5: 1 | U5: 1 | V5: 1 | W5: 1 | X5: =IFERROR(MAX(S5:W5),"") -> 1 | Y5: 1 | Z5: =IF(OR(ISBLANK(L5),ISBLANK(l)),"",VLOOKUP(X5-0,'2_Risk_Criteria'!$D$4:$I$9,Y5+1,0)) -> L1
A6: 3 | B6: Hardware | C6: Hardware | D6: A | E6: เครื่อง Notebook ใช้งานไม่ได้เนื่องจากการตั้งค่าอุปกรณ์ไม่ถูกต้อง (Config) | F6: 1.มีการฝึกอบรมให้ความรู้กับพนักงานใหม่ 2.จัดทำคู่มือการตั้งค่าอุปกรณ์ | G6: 1 | H6: 2 | I6: 1 | J6: 1 | K6: 2 | L6: =IFERROR(MAX(G6:K6),"") -> 2 | M6: 5 | N6: =IF(ISBLANK(L6),"",VLOOKUP(L6,'2_Risk_Criteria'!$D$4:$I$9,M6+1,0)) -> M10 | O6: =VLOOKUP(N6,'2_Risk_Criteria'!$I$28:$J$42,2,0) -> Control | P6: 1.ฝึกอบรมทักษะความรู้ ทุก 6 เดือน 2.ทบทวนเอกสารคู่มือการใช้งาน ทุก 1 ปี 3.ทดสอบความรู้ 4.ส่งพนักงานฝึกอบรมภายนอก เพื่อเพิ่มความรู้ ความสามารถ (Competency) 5.ตั้งตัวชี้วัด KPI เพื่อประเมินหน่วยงาน | S6: 1 | T6: 1 | U6: 1 | V6: 1 | W6: 1 | X6: =IFERROR(MAX(S6:W6),"") -> 1 | Y6: 1 | Z6: =IF(OR(ISBLANK(L6),ISBLANK(l)),"",VLOOKUP(X6-0,'2_Risk_Criteria'!$D$4:$I$9,Y6+1,0)) -> L1
A7: 4 | B7: Hardware | C7: Hardware | D7: A | E7: เครื่อง Notebook ใช้งานไม่ได้ เนื่องจากขาดการตรวจสอบและการบำรุงรักษาไม่เพียงพอ | F7: 1.จัดทำแผนในการทำความสะอาดและตรวจสอบเครื่องอย่างน้อยปีละ 1 ครั้ง 2.จัดเตรียมเครื่องคอมพิวเตอร์และอะไหล่สำรอง เมื่อมีการชำรุดเสียหาย | G7: 1 | H7: 3 | I7: 2 | J7: 1 | K7: 1 | L7: =IFERROR(MAX(G7:K7),"") -> 3 | M7: 4 | N7: =IF(ISBLANK(L7),"",VLOOKUP(L7,'2_Risk_Criteria'!$D$4:$I$9,M7+1,0)) -> H12 | O7: =VLOOKUP(N7,'2_Risk_Criteria'!$I$28:$J$42,2,0) -> Transfer | P7: 1.จัดทำทะเบียนทรัพย์สินสารสนเทศ 2.จัดทำนโยบายสำรวจทรัพย์สินปีละ 1 ครั้ง 3.วางแผนการบริหารจัดการเครื่องสำรองให้เพียงพอ 4.จัดหาโปรแกรมบริหารจัดการทรัพย์สิน เพื่อตรวจสอบทรัพย์สิน | S7: 1 | T7: 2 | U7: 2 | V7: 1 | W7: 1 | X7: =IFERROR(MAX(S7:W7),"") -> 2 | Y7: 2 | Z7: =IF(OR(ISBLANK(L7),ISBLANK(l)),"",VLOOKUP(X7-0,'2_Risk_Criteria'!$D$4:$I$9,Y7+1,0)) -> L4
A8: 5 | B8: Hardware | C8: Hardware | D8: C , A | E8: เครื่อง Notebook (เชื่อมต่อเครือข่ายภายนอก) ถูกครอบครองจากผู้ไม่ประสงค์ดี เนื่องจาก ไม่มีการป้องกันการเชื่อมต่อเครือข่ายสาธารณะ เช่น ใช้ Firewall ป้องกัน | F8: 1.นโยบายการเชื่อมต่อเครือข่ายภายนอก 2.มี Firewall กั้นระหว่างการเชื่อมต่อ 3.มีการควบคุมการเชื่อมต่อของผู้ให้บริการภายนอกต้องได้รับอนุญาตจากเจ้าหน้าที่ฝ่าย IT 4.มีการควบคุมและตรวจสอบเครื่องคอมพิวเตอร์ของผู้ให้บริการภายนอกก่อนนำอุปกรณ์มาเชื่อมต่อระบบ Network ภายใน เช่น Antivirus, Full scan,Virus show log scan ต่อเจ้าหน้าที่ IT | G8: 1 | H8: 3 | I8: 2 | J8: 1 | K8: 1 | L8: =IFERROR(MAX(G8:K8),"") -> 3 | M8: 2 | N8: =IF(ISBLANK(L8),"",VLOOKUP(L8,'2_Risk_Criteria'!$D$4:$I$9,M8+1,0)) -> M6 | O8: =VLOOKUP(N8,'2_Risk_Criteria'!$I$28:$J$42,2,0) -> Control | P8: 1.นโยบายการเชื่อมต่อเครือข่ายภายนอก 2.มี Firewall กั้นระหว่างการเชื่อมต่อ 3.มีการควบคุมการเชื่อมต่อของผู้ให้บริการภายนอกต้องได้รับอนุญาตจากฝ่าย IT 4.มีการควบคุมและตรวจสอบเครื่องคอมพิวเตอร์ของผู้ให้บริการภายนอกก่อนนำอุปกรณ์มาเชื่อมต่อระบบ Network ภายใน เช่น Antivirus, Full scan,Virus show log scan ต่อเจ้าหน้าที่ IT | S8: 1 | T8: 2 | U8: 1 | V8: 1 | W8: 1 | X8: =IFERROR(MAX(S8:W8),"") -> 2 | Y8: 1 | Z8: =IF(OR(ISBLANK(L8),ISBLANK(l)),"",VLOOKUP(X8-0,'2_Risk_Criteria'!$D$4:$I$9,Y8+1,0)) -> L2
A9: 6 | B9: Hardware | C9: Hardware | D9: A | E9: เครื่อง Notebook ใช้งานไม่ได้ เนื่องจากถูกเจาะระบบ (Hack) โดย Hacker หรือผู้ไม่ประสงค์ดี | F9: 1.นโยบายไม่ให้นำอุปกรณ์สื่อบันทึกข้อมูลแบบพกพามาเชื่อมต่อ 2.ติดตั้ง Jamf Pro มี Policy Device control 3.ติดตั้งโปรแกรม Antivirus ที่มี Auto Update | G9: 1 | H9: 3 | I9: 2 | J9: 1 | K9: 1 | L9: =IFERROR(MAX(G9:K9),"") -> 3 | M9: 1 | N9: =IF(ISBLANK(L9),"",VLOOKUP(L9,'2_Risk_Criteria'!$D$4:$I$9,M9+1,0)) -> L3 | O9: =VLOOKUP(N9,'2_Risk_Criteria'!$I$28:$J$42,2,0) -> Accept | P9: 1.นโยบายไม่ให้นำอุปกรณ์สื่อบันทึกข้อมูลแบบพกพามาเชื่อมต่อ 2.ติดตั้ง Jamf Pro มี Policy Device control 3.ติดตั้งโปรแกรม Antivirus ที่มี Auto Update 4. | S9: 1 | T9: 2 | U9: 2 | V9: 1 | W9: 1 | X9: =IFERROR(MAX(S9:W9),"") -> 2 | Y9: 1 | Z9: =IF(OR(ISBLANK(L9),ISBLANK(l)),"",VLOOKUP(X9-0,'2_Risk_Criteria'!$D$4:$I$9,Y9+1,0)) -> L2
A10: 7 | B10: Network | C10: Network | D10: C | E10: ผู้ไม่มีสิทธิ สามารถเข้าถึงอุปกรณ์ซึ่งติดตั้งอยู่ใน Rack Network ได้ เนื่องจากขาดการตรวจสอบและทบทวนสิทธิ์ได้ เนื่องจากไม่มีการจำกัดและควบคุมสิทธิ์การเข้า-ออก | F10: 1.ผู้ให้บริการภายนอก - มีการควบคุมและติดตามเมื่อเข้ามาในพื้นที่ให้บริการ - มีการบันทึก Log การเข้า-ออก Network Rack โซน - มีการควบคุมการเข้าออกโดย Access Control - มีการแจ้งล่วงหน้าก่อนเข้ามาปฏิบัติงาน Network Rack โซน 2.เจ้าหน้าที่ภายใน เฉพาะผู้ได้รับสิทธิหรือผู้ที่ได้รับอนุญาต - ได้รับอนุญาตจากเจ้าหน้าที่ฝ่าย IT 3.ระบบ CCTV | G10: 3 | H10: 3 | I10: 3 | J10: 1 | K10: 2 | L10: =IFERROR(MAX(G10:K10),"") -> 3 | M10: 1 | N10: =IF(ISBLANK(L10),"",VLOOKUP(L10,'2_Risk_Criteria'!$D$4:$I$9,M10+1,0)) -> L3 | O10: =VLOOKUP(N10,'2_Risk_Criteria'!$I$28:$J$42,2,0) -> Accept | P10: 1.ผู้ให้บริการภายนอก - แจ้งชื่อผู้เข้าปฏิบัติงานในพื้นที่ ล่วงหน้า1 วัน ก่อนเข้าปฏิบัติงาน - พิสูจน์ตัวตนของบุคคล เช่น บัตรประจำตัวประชาชน 2.แบ่งพื้นที่ที่รักษาความมั่นคงปลอดภัย 3.ควบคุมการเข้า-ออกพื้นที่ 4.กำหนดผู้มีสิทธิการเข้าถึงพื้นที่ที่รักษาความมั่นคงปลอดภัย (Zone A) 5.ทบทวนผู้มีสิทธิการเข้าถึงพื้นที่ที่รักษาความมั่นคงปลอดภัย (Zone A) ปีละ 1 ครั้ง 6.จัดพื้นที่สำหรับรับ - ส่งของ (Loading Area) ก่อนนำอุปกรณ์หรือสิ่งของเข้าพื้นที่ | S10: 2 | T10: 2 | U10: 2 | V10: 1 | W10: 1 | X10: =IFERROR(MAX(S10:W10),"") -> 2 | Y10: 1 | Z10: =IF(OR(ISBLANK(L10),ISBLANK(l)),"",VLOOKUP(X10-0,'2_Risk_Criteria'!$D$4:$I$9,Y10+1,0)) -> L2
A11: 8 | B11: Network | C11: Network | D11: C | E11: ผู้ไม่มีสิทธิ์สามารถเข้าถึงอุปกรณ์ซึ่งติดตั้งอยู่ใน Rack Network ได้ เนื่องจากขาดการตรวจสอบและทบทวนสิทธิการเข้าถึง | F11: 1.มีการกำหนดสิทธิการเข้าถึงข้อมูล 2.มีโนยบายควบคุมการเผยแพร่ข้อมูล 3.ได้รับอนุญาตจากเจ้าหน้าที่ฝ่าย IT | G11: 1 | H11: 2 | I11: 2 | J11: 1 | K11: 1 | L11: =IFERROR(MAX(G11:K11),"") -> 2 | M11: 1 | N11: =IF(ISBLANK(L11),"",VLOOKUP(L11,'2_Risk_Criteria'!$D$4:$I$9,M11+1,0)) -> L2 | O11: =VLOOKUP(N11,'2_Risk_Criteria'!$I$28:$J$42,2,0) -> Accept | P11: 1.ผู้ให้บริการภายนอก - แจ้งชื่อผู้เข้าปฏิบัติงานในพื้นที่ ล่วงหน้า1 วัน ก่อนเข้าปฏิบัติงาน - พิสูจน์ตัวตนของบุคคล เช่น บัตรประจำตัวประชาชน 2.แบ่งพื้นที่ที่รักษาความมั่นคงปลอดภัย 3.ควบคุมการเข้า-ออกพื้นที่ 4.กำหนดผู้มีสิทธิการเข้าถึงพื้นที่ที่รักษาความมั่นคงปลอดภัย (Zone A) 5.ทบทวนผู้มีสิทธิการเข้าถึงพื้นที่ที่รักษาความมั่นคงปลอดภัย (Zone A) ปีละ 1 ครั้ง 6.จัดพื้นที่สำหรับรับ - ส่งของ (Loading Area) ก่อนนำอุปกรณ์หรือสิ่งของเข้าพื้นที่ | S11: 1 | T11: 2 | U11: 1 | V11: 1 | W11: 1 | X11: =IFERROR(MAX(S11:W11),"") -> 2 | Y11: 1 | Z11: =IF(OR(ISBLANK(L11),ISBLANK(l)),"",VLOOKUP(X11-0,'2_Risk_Criteria'!$D$4:$I$9,Y11+1,0)) -> L2
A12: 9 | B12: Network | C12: Network | D12: C | E12: ผู้ไม่มีสิทธิ์สามารถเข้าถึงอุปกรณ์ซึ่งติดตั้งอยู่ใน Rack Network ได้ เนื่องจากอุปกรณ์ติดตั้งในตู้ซึ่งไม่มีการล็อค | F12: 1.มีการควบคุมและติดตามผู้ให้บริการภายนอกระหว่างปฏิบัติงาน 2.ผู้ให้บริการภายนอกแจ้งล่วงหน้าก่อนเข้าปฏิบัติงาน | G12: 1 | H12: 2 | I12: 2 | J12: 1 | K12: 1 | L12: =IFERROR(MAX(G12:K12),"") -> 2 | M12: 1 | N12: =IF(ISBLANK(L12),"",VLOOKUP(L12,'2_Risk_Criteria'!$D$4:$I$9,M12+1,0)) -> L2 | O12: =VLOOKUP(N12,'2_Risk_Criteria'!$I$28:$J$42,2,0) -> Accept | P12: 1.ผู้ให้บริการภายนอก - แจ้งชื่อผู้เข้าปฏิบัติงานในพื้นที่ ล่วงหน้า1 วัน ก่อนเข้าปฏิบัติงาน - พิสูจน์ตัวตนของบุคคล เช่น บัตรประจำตัวประชาชน 2.แบ่งพื้นที่ที่รักษาความมั่นคงปลอดภัย 3.ควบคุมการเข้า-ออกพื้นที่ 4.กำหนดผู้มีสิทธิการเข้าถึงพื้นที่ที่รักษาความมั่นคงปลอดภัย (Zone A) 5.ทบทวนผู้มีสิทธิการเข้าถึงพื้นที่ที่รักษาความมั่นคงปลอดภัย (Zone A) ปีละ 1 ครั้ง 6.จัดพื้นที่สำหรับรับ - ส่งของ (Loading Area) ก่อนนำอุปกรณ์หรือสิ่งของเข้าพื้นที่ | S12: 1 | T12: 2 | U12: 1 | V12: 1 | W12: 1 | X12: =IFERROR(MAX(S12:W12),"") -> 2 | Y12: 1 | Z12: =IF(OR(ISBLANK(L12),ISBLANK(l)),"",VLOOKUP(X12-0,'2_Risk_Criteria'!$D$4:$I$9,Y12+1,0)) -> L2
A13: 10 | B13: Network | C13: Network | D13: C | E13: ผู้ไม่มีสิทธิ์อาจสามารถเข้าถึงอุปกรณ์ได้เนื่องจากการเบิก/เก็บ/ใช้ กุญแจที่ใช้ล็อคตู้อุปกรณ์ไม่มีวิธีการควบคุมและตรวจสอบ | F13: 1.มีการ Reset เครื่องสแกนลายนิ้วมือทุก 1 ปี หรือดำเนินการทันทีเมือมีพนักงานพ้นสภาพ | G13: 2 | H13: 2 | I13: 2 | J13: 1 | K13: 1 | L13: =IFERROR(MAX(G13:K13),"") -> 2 | M13: 1 | N13: =IF(ISBLANK(L13),"",VLOOKUP(L13,'2_Risk_Criteria'!$D$4:$I$9,M13+1,0)) -> L2 | O13: =VLOOKUP(N13,'2_Risk_Criteria'!$I$28:$J$42,2,0) -> Accept | P13: 1.มีการบันทึกยืม - คืนกุญแจ 2.มีผู้รับผิดชอบควบคุม จัดเก็บกุญแจ 3.จัดเก็บกุญแจในพื้นที่ที่ปลอดภัย 4.ควบคุมและติดตามผู้ให้บริการภายนอกเมื่อเข้ามาปฏิบัติงาน | S13: 1 | T13: 2 | U13: 2 | V13: 1 | W13: 1 | X13: =IFERROR(MAX(S13:W13),"") -> 2 | Y13: 1 | Z13: =IF(OR(ISBLANK(L13),ISBLANK(l)),"",VLOOKUP(X13-0,'2_Risk_Criteria'!$D$4:$I$9,Y13+1,0)) -> L2
A14: 11 | B14: Network | C14: Network | D14: C | E14: อุปกรณ์เน็ตเวิร์คและค่าการทำงาน ถูกเปลี่ยนแปลงแก้ไขสิทธิ์การเข้าถึงจากผู้ดูแล โดยไม่ได้ดำเนินการตามขั้นตอนที่กำหนดไว้ | F14: 1.ผู้ดูแลผ่านการฝึกอบรมการตั้งค่าอุปกรณ์เน็ตเวิร์คจากผู้ให้บริการภายนอก 2.การตั้งค่าเน็ตเวิร์คสามารถตั้งค่าได้จากผู้เชี่ยวชาญ 3.มีการ BackUp Config 4.เจ้าหน้า IT Support สามารถแก้ไขเบื้องต้นได้ตามที่ผู้ให้บริการภายนอกกำหนดได้เท่านั้น เช่น Port Security, Change port Vlan | G14: 1 | H14: 1 | I14: 1 | J14: 1 | K14: 1 | L14: =IFERROR(MAX(G14:K14),"") -> 1 | M14: 2 | N14: =IF(ISBLANK(L14),"",VLOOKUP(L14,'2_Risk_Criteria'!$D$4:$I$9,M14+1,0)) -> L2 | O14: =VLOOKUP(N14,'2_Risk_Criteria'!$I$28:$J$42,2,0) -> Accept | P14: 1.ผู้ดูแลผ่านการฝึกอบรมการตั้งค่าอุปกรณ์เน็ตเวิร์คจากผู้ให้บริการภายนอก 2.การตั้งค่าเน็ตเวิร์คสามารถตั้งค่าได้จากผู้เชี่ยวชาญ 3.มีการ BackUp Config 4.เจ้าหน้า IT Support สามารถแก้ไขเบื้องต้นได้ตามที่ผู้ให้บริการภายนอกกำหนดได้เท่านั้น เช่น Port Security, Change port Vlan | S14: 1 | T14: 1 | U14: 1 | V14: 1 | W14: 1 | X14: =IFERROR(MAX(S14:W14),"") -> 1 | Y14: 2 | Z14: =IF(OR(ISBLANK(L14),ISBLANK(l)),"",VLOOKUP(X14-0,'2_Risk_Criteria'!$D$4:$I$9,Y14+1,0)) -> L2
A15: 12 | B15: Network | C15: Network | D15: C | E15: โดนเจาะระบบ (Hacking) โดย Hacker หรือผู้ไม่ประสงค์ดี เนื่องจากไม่มีการควบคุมการเชื่อมต่อกับภายนอก (Public network connection) | F15: 1.มี Firewall กั้นระหว่างการเชื่อมต่อ 2.มีการควบคุมการเชื่อมต่อของผู้ให้บริการภายนอกต้องได้รับอนุญาตจากเจ้าหน้าที่ฝ่าย IT | G15: 1 | H15: 2 | I15: 2 | J15: 1 | K15: 1 | L15: =IFERROR(MAX(G15:K15),"") -> 2 | M15: 1 | N15: =IF(ISBLANK(L15),"",VLOOKUP(L15,'2_Risk_Criteria'!$D$4:$I$9,M15+1,0)) -> L2 | O15: =VLOOKUP(N15,'2_Risk_Criteria'!$I$28:$J$42,2,0) -> Accept | P15: 1.มี Firewall กั้นระหว่างการเชื่อมต่อ 2.มีการควบคุมการเชื่อมต่อของผู้ให้บริการภายนอกต้องได้รับอนุญาตจากเจ้าหน้าที่ฝ่าย IT | S15: 1 | T15: 2 | U15: 2 | V15: 1 | W15: 1 | X15: =IFERROR(MAX(S15:W15),"") -> 2 | Y15: 1 | Z15: =IF(OR(ISBLANK(L15),ISBLANK(l)),"",VLOOKUP(X15-0,'2_Risk_Criteria'!$D$4:$I$9,Y15+1,0)) -> L2
... A22: 19 | B22: Network | C22: Network | D22: A | E22: อุปกรณ์เน็ตเวิร์ค หยุดชะงักใช้งานไม่ได้ เนื่องจากไฟฟ้าขัดข้อง และไม่มีไฟฟ้าสำรอง | F22: 1.ระบบไฟฟ้าและระบบไฟสำรองของอาคาร(ควบคุมโดยฝ่ายอาคาร) 2.ระบบสำรองไฟของฝ่าย IT (Network Rack) 3.การทดสอบไฟฟ้าสำรอง 1 ปีต่อครั้ง | G22: 1 | H22: 2 | I22: 1 | J22: 1 | K22: 3 | L22: =IFERROR(MAX(G22:K22),"") -> 3 | M22: 3 | N22: =IF(ISBLANK(L22),"",VLOOKUP(L22,'2_Risk_Criteria'!$D$4:$I$9,M22+1,0)) -> M9 | O22: =VLOOKUP(N22,'2_Risk_Criteria'!$I$28:$J$42,2,0) -> Control | P22: 1.ระบบไฟฟ้าและระบบไฟสำรองของอาคาร(ควบคุมโดยฝ่ายอาคาร) 2.ระบบสำรองไฟของฝ่าย IT (Network Rack) 3.การทดสอบไฟฟ้าสำรอง 1 ปีต่อครั้ง | S22: 1 | T22: 1 | U22: 1 | V22: 1 | W22: 1 | X22: =IFERROR(MAX(S22:W22),"") -> 1 | Y22: 2 | Z22: =IF(OR(ISBLANK(L22),ISBLANK(l)),"",VLOOKUP(X22-0,'2_Risk_Criteria'!$D$4:$I$9,Y22+1,0)) -> L2
A23: 20 | B23: Network | C23: Network | D23: A | E23: อุปกรณ์เน็ตเวิร์ค ใช้งานไม่ได้ เนื่องจากไฟไหม้ | F23: 1.ระบบอัคคีภัยทั้งบริษัทควบคุมโดยฝ่ายอาคาร 2.มีแผนรองรับสถานการณ์ฉุกเฉินทางอัคคีภัย 3.มีถังดับเพลิงสำหรับกรณีฉุกเฉิน 4.ระบบ Smoke detector และ fire Alarm 5.CCTV Monitoring | G23: 1 | H23: 4 | I23: 1 | J23: 3 | K23: 1 | L23: =IFERROR(MAX(G23:K23),"") -> 4 | M23: 1 | N23: =IF(ISBLANK(L23),"",VLOOKUP(L23,'2_Risk_Criteria'!$D$4:$I$9,M23+1,0)) -> L4 | O23: =VLOOKUP(N23,'2_Risk_Criteria'!$I$28:$J$42,2,0) -> Accept | P23: 1.ให้ปฏิบัติตาม XXX-QP-IT-003 Working in Secure Area (แนวปฏิบัติเกี่ยวกับการปฏิบัติงานในพื้นที่ที่ต้องรักษาความมั่นคงปลอดภัย ) 2.ให้บันทึกตาม XXX-FM-IT-016 แบบฟอร์มตรวจเช็คระบบประจำวัน 3.ให้บันทึกตาม XXX-FM-IT-017 แบบฟอร์มตารางตรวจเช็คอุปกรณ์สนับสนุน 4.ซ้อมแผนไฟไหม้ปีละ 1 ครั้ง ที่จัดขึ้นโดยฝ่ายอาคาร The Trendy Office | R23: RTP-001 | S23: 1 | T23: 3 | U23: 1 | V23: 2 | W23: 1 | X23: =IFERROR(MAX(S23:W23),"") -> 3 | Y23: 1 | Z23: =IF(OR(ISBLANK(L23),ISBLANK(l)),"",VLOOKUP(X23-0,'2_Risk_Criteria'!$D$4:$I$9,Y23+1,0)) -> L3
A24: 21 | B24: Network | C24: Network | D24: A | E24: อุปกรณ์เน็ตเวิร์ค ทำงานล้มเหลว เนื่องจากการควบคุมสภาพแวดล้อมของอุปกรณ์ไม่เหมาะสมตามที่ผู้ผลิตแนะนำ | F24: 1.มีการจัดเก็บอุปกรณ์ในตู้ Rack ที่เหมาะสม 2.มีระบบ Monitor 3.มีการตรวจสอบอุปกรณ์ | G24: 1 | H24: 1 | I24: 1 | J24: 1 | K24: 1 | L24: =IFERROR(MAX(G24:K24),"") -> 1 | M24: 1 | N24: =IF(ISBLANK(L24),"",VLOOKUP(L24,'2_Risk_Criteria'!$D$4:$I$9,M24+1,0)) -> L1 | O24: =VLOOKUP(N24,'2_Risk_Criteria'!$I$28:$J$42,2,0) -> Accept | P24: 1.มีการจัดเก็บอุปกรณ์ในตู้ Rack ที่เหมาะสม 2.มีระบบ Monitor 3.มีการตรวจสอบอุปกรณ์ | S24: 1 | T24: 1 | U24: 1 | V24: 1 | W24: 1 | X24: =IFERROR(MAX(S24:W24),"") -> 1 | Y24: 1 | Z24: =IF(OR(ISBLANK(L24),ISBLANK(l)),"",VLOOKUP(X24-0,'2_Risk_Criteria'!$D$4:$I$9,Y24+1,0)) -> L1
A25: 22 | B25: Network | C25: Network | D25: A | E25: Network เกิดความไม่พร้อมใช้ เนื่องจากไม่มีการวางแผนและซ้อมแผนความไม่ต่อเนื่อง (Business Continuity Management) | F25: 1.มีการวางแผนรับสถานการณ์ Network ใช้งานไม่ได้ | G25: 1 | H25: 2 | I25: 1 | J25: 1 | K25: 1 | L25: =IFERROR(MAX(G25:K25),"") -> 2 | M25: 2 | N25: =IF(ISBLANK(L25),"",VLOOKUP(L25,'2_Risk_Criteria'!$D$4:$I$9,M25+1,0)) -> L4 | O25: =VLOOKUP(N25,'2_Risk_Criteria'!$I$28:$J$42,2,0) -> Accept | P25: 1.มีระบบ Monitor ระบบ Network 2.วางแผนและซ้อมแผนความไม่ต่อเนื่อง (Business Continuity Management) ทุก 1 ปี | S25: 1 | T25: 1 | U25: 1 | V25: 1 | W25: 1 | X25: =IFERROR(MAX(S25:W25),"") -> 1 | Y25: 2 | Z25: =IF(OR(ISBLANK(L25),ISBLANK(l)),"",VLOOKUP(X25-0,'2_Risk_Criteria'!$D$4:$I$9,Y25+1,0)) -> L2
A26: 23 | B26: Operating system | C26: Software | D26: A | E26: ซอฟต์แวร์ไม่สามารถใช้งาน เนื่องจากไม่มีการติดตามและ Upgrade Version ที่เหมาะสม | F26: 1.มีการทดสอบ Software Version ล่าสุดว่ามีผลกระทบต่อระบบการใช้งานก่อนนำมาใช้งานจริง | G26: 1 | H26: 1 | I26: 1 | J26: 1 | K26: 1 | L26: =IFERROR(MAX(G26:K26),"") -> 1 | M26: 3 | N26: =IF(ISBLANK(L26),"",VLOOKUP(L26,'2_Risk_Criteria'!$D$4:$I$9,M26+1,0)) -> L3 | O26: =VLOOKUP(N26,'2_Risk_Criteria'!$I$28:$J$42,2,0) -> Accept | P26: 1.มีการทดสอบ Software Version ล่าสุดว่ามีผลกระทบต่อระบบการใช้งานก่อนนำมาใช้งานจริง | S26: 1 | T26: 1 | U26: 1 | V26: 1 | W26: 1 | X26: =IFERROR(MAX(S26:W26),"") -> 1 | Y26: 3 | Z26: =IF(OR(ISBLANK(L26),ISBLANK(l)),"",VLOOKUP(X26-0,'2_Risk_Criteria'!$D$4:$I$9,Y26+1,0)) -> L3
A27: 24 | B27: Software Package | C27: Software | D27: C | E27: ผู้ไม่มีสิทธิสามารถติดตั้งซอฟต์แวร์สำเร็จรูป (Software Package) ได้ เนื่องจากไม่มีการกำหนดและควบคุมสิทธิที่เหมาะสม | F27: 1.มีการควบคุมสิทธิผู้ที่สามารถติดตั้งซอฟต์แวร์ 2.มีแบบฟอร์มขอติดตั้ง Software ผ่านระบบ Ticket IT Help Center 3.ผ่านการอนุมัติจาก Team manager 4.นโยบายไม่ให้นำอุปกรณ์สื่อบันทึกข้อมูลแบบพกพามาเชื่อมต่อ 5.มีนโยบายควบคุมการติดตั้ง Software | G27: 1 | H27: 1 | I27: 1 | J27: 1 | K27: 2 | L27: =IFERROR(MAX(G27:K27),"") -> 2 | M27: 2 | N27: =IF(ISBLANK(L27),"",VLOOKUP(L27,'2_Risk_Criteria'!$D$4:$I$9,M27+1,0)) -> L4 | O27: =VLOOKUP(N27,'2_Risk_Criteria'!$I$28:$J$42,2,0) -> Accept | P27: 1.มีการควบคุมสิทธิผู้ที่สามารถติดตั้งซอฟต์แวร์ 2.มีแบบฟอร์มขอติดตั้ง Software ผ่านระบบ Ticket IT Help Center 3.ผ่านการอนุมัติจาก Team manager 4.นโยบายไม่ให้นำอุปกรณ์สื่อบันทึกข้อมูลแบบพกพามาเชื่อมต่อ 5.มีนโยบายควบคุมการติดตั้ง Software | S27: 1 | T27: 1 | U27: 1 | V27: 1 | W27: 1 | X27: =IFERROR(MAX(S27:W27),"") -> 1 | Y27: 2 | Z27: =IF(OR(ISBLANK(L27),ISBLANK(l)),"",VLOOKUP(X27-0,'2_Risk_Criteria'!$D$4:$I$9,Y27+1,0)) -> L2
A28: 25 | B28: Software Package | C28: Software | D28: C | E28: ผู้ไม่มีสิทธิสามารถ Copy ซอฟต์แวร์สำเร็จรูป (Software Package) ไปนอกองค์กรได้ เนื่องจากไม่มีการกำหนดและควบคุมสิทธิที่เหมาะสม | F28: 1.นโยบายไม่ให้นำอุปกรณ์สื่อบันทึกข้อมูลแบบพกพามาเชื่อมต่อ 2. มีโปรแกรม MDM Jamf Pro ตั้งค่า Device Control 3.มีการควบคุมการนำข้อมูลออกจากระบบภายใน | G28: 1 | H28: 1 | I28: 1 | J28: 1 | K28: 2 | L28: =IFERROR(MAX(G28:K28),"") -> 2 | M28: 1 | N28: =IF(ISBLANK(L28),"",VLOOKUP(L28,'2_Risk_Criteria'!$D$4:$I$9,M28+1,0)) -> L2 | O28: =VLOOKUP(N28,'2_Risk_Criteria'!$I$28:$J$42,2,0) -> Accept | P28: 1.นโยบายไม่ให้นำอุปกรณ์สื่อบันทึกข้อมูลแบบพกพามาเชื่อมต่อ 2. มีโปรแกรม MDM Jamf Pro ตั้งค่า Device Control 3.มีการควบคุมการนำข้อมูลออกจากระบบภายใน | S28: 1 | T28: 1 | U28: 1 | V28: 1 | W28: 2 | X28: =IFERROR(MAX(S28:W28),"") -> 2 | Y28: 1 | Z28: =IF(OR(ISBLANK(L28),ISBLANK(l)),"",VLOOKUP(X28-0,'2_Risk_Criteria'!$D$4:$I$9,Y28+1,0)) -> L2
A29: 26 | B29: Software Package | C29: Software | D29: C | E29: ซอฟต์แวร์สำเร็จรูป (Software Package) ถูกเผยแพร่ สำเนาหรือเข้าถึงได้ เนื่องจากการตรวจสอบและจัดการอุปกรณ์จัดเก็บข้อมูลบนเครื่องคอมพิวเตอร์ก่อนการส่งซ่อม หรือจำหน่ายทิ้งไม่มีประสิทธิผล | F29: 1.มีการจัด Format อุปกรณ์ก่อนนำส่งซ่อม หรือ ทำลายก่อนจำหน่าย | G29: 1 | H29: 1 | I29: 3 | J29: 1 | K29: 1 | L29: =IFERROR(MAX(G29:K29),"") -> 3 | M29: 1 | N29: =IF(ISBLANK(L29),"",VLOOKUP(L29,'2_Risk_Criteria'!$D$4:$I$9,M29+1,0)) -> L3 | O29: =VLOOKUP(N29,'2_Risk_Criteria'!$I$28:$J$42,2,0) -> Accept | P29: 1.มีการจัด Format อุปกรณ์ก่อนนำส่งซ่อม หรือ ทำลายก่อนจำหน่าย | S29: 1 | T29: 1 | U29: 2 | V29: 1 | W29: 1 | X29: =IFERROR(MAX(S29:W29),"") -> 2 | Y29: 1 | Z29: =IF(OR(ISBLANK(L29),ISBLANK(l)),"",VLOOKUP(X29-0,'2_Risk_Criteria'!$D$4:$I$9,Y29+1,0)) -> L2
A30: 27 | B30: Software Package | C30: Software | D30: I | E30: ซอฟต์แวร์สำเร็จรูป (Software Package) ทำงานผิดปกติจากไวรัสคอมพิวเตอร์แพร่ระบาด เนื่องจากการติดตามและป้องกันไวรัสคอมพิวเตอร์ไม่มีประสิทธิผล | F30: 1.มีการควบคุมและติดตาม Update Virus อย่างน้อย 3 วัน 2.นโยบายไม่ให้นำอุปกรณ์สื่อบันทึกข้อมูลแบบพกพามาเชื่อมต่อ 3. มีโปรแกรม MDM Jamf Pro ตั้งค่า Device Control 4.มีระบบ Monitor 5.มีการรายงานความผิดปกติ Antivirus | G30: 1 | H30: 3 | I30: 1 | J30: 1 | K30: 2 | L30: =IFERROR(MAX(G30:K30),"") -> 3 | M30: 1 | N30: =IF(ISBLANK(L30),"",VLOOKUP(L30,'2_Risk_Criteria'!$D$4:$I$9,M30+1,0)) -> L3 | O30: =VLOOKUP(N30,'2_Risk_Criteria'!$I$28:$J$42,2,0) -> Accept | P30: 1.มีการตรวจสอบการ Update Virus โดย Assistant IT Support Manager 2.นำ Event Log มาทบทวนและวิเคราะห์หาสาเหตุสัปดาห์ละ 1 ครั้ง | S30: 1 | T30: 3 | U30: 1 | V30: 1 | W30: 1 | X30: =IFERROR(MAX(S30:W30),"") -> 3 | Y30: 1 | Z30: =IF(OR(ISBLANK(L30),ISBLANK(l)),"",VLOOKUP(X30-0,'2_Risk_Criteria'!$D$4:$I$9,Y30+1,0)) -> L3
A31: 28 | B31: Software Package | C31: Software | D31: A | E31: ซอฟต์แวร์สำเร็จรูป (Software Package) ล้มเหลว/เสียหาย ไม่สามารถกู้คืนระบบได้ตามระยะเวลาที่กำหนด เนื่องจากไม่มีการสำรองซอฟต์แวร์ (Backup) | F31: 1.ใช้ Software ที่เป็น Service ของผู้ให้บริการที่มีการ Backup ให้ 2.จัดเก็บใน Share Drive มีการกำหนดสิทธิการเข้าถึง | G31: 1 | H31: 3 | I31: 1 | J31: 1 | K31: 3 | L31: =IFERROR(MAX(G31:K31),"") -> 3 | M31: 1 | N31: =IF(ISBLANK(L31),"",VLOOKUP(L31,'2_Risk_Criteria'!$D$4:$I$9,M31+1,0)) -> L3 | O31: =VLOOKUP(N31,'2_Risk_Criteria'!$I$28:$J$42,2,0) -> Accept | P31: 1.ใช้ Softwae ที่เป็น Service ของผู้ให้บริการที่มีการ Backup ให้ 2.จัดเก็บใน Share Drive มีการกำหนดสิทธิการเข้าถึง | S31: 1 | T31: 3 | U31: 1 | V31: 1 | W31: 2 | X31: =IFERROR(MAX(S31:W31),"") -> 3 | Y31: 1 | Z31: =IF(OR(ISBLANK(L31),ISBLANK(l)),"",VLOOKUP(X31-0,'2_Risk_Criteria'!$D$4:$I$9,Y31+1,0)) -> L3
A32: 29 | B32: Electronic File | C32: Data and Information | D32: C | E32: ข้อมูลสำรอง (Backup data) ถูกเปิดเผย/เข้าถึงจากผู้ไม่มีสิทธิ | F32: 1.จัดเก็บไว้บน Share Drive 2.มีการกำหนดสิทธิการเข้าถึง | G32: 1 | H32: 1 | I32: 2 | J32: 1 | K32: 3 | L32: =IFERROR(MAX(G32:K32),"") -> 3 | M32: 1 | N32: =IF(ISBLANK(L32),"",VLOOKUP(L32,'2_Risk_Criteria'!$D$4:$I$9,M32+1,0)) -> L3 | O32: =VLOOKUP(N32,'2_Risk_Criteria'!$I$28:$J$42,2,0) -> Accept | P32: 1.จัดเก็บไว้บน Share Drive 2.มีการกำหนดสิทธิการเข้าถึง | S32: 1 | T32: 1 | U32: 2 | V32: 1 | W32: 2 | X32: =IFERROR(MAX(S32:W32),"") -> 2 | Y32: 1 | Z32: =IF(OR(ISBLANK(L32),ISBLANK(l)),"",VLOOKUP(X32-0,'2_Risk_Criteria'!$D$4:$I$9,Y32+1,0)) -> L2
A33: 30 | B33: Electronic File | C33: Data and Information | D33: I | E33: ข้อมูลสำรอง (Backup data) ถูกเปลี่ยนแปลงแก้ไข โดยผู้ไม่มีสิทธิ | F33: 1.จัดเก็บไว้บน Share Drive 2.มีการกำหนดสิทธิการเข้าถึง | G33: 1 | H33: 1 | I33: 1 | J33: 1 | K33: 3 | L33: =IFERROR(MAX(G33:K33),"") -> 3 | M33: 1 | N33: =IF(ISBLANK(L33),"",VLOOKUP(L33,'2_Risk_Criteria'!$D$4:$I$9,M33+1,0)) -> L3 | O33: =VLOOKUP(N33,'2_Risk_Criteria'!$I$28:$J$42,2,0) -> Accept | P33: 1.จัดเก็บไว้บน Share Drive 2.มีการกำหนดสิทธิการเข้าถึง | S33: 1 | T33: 1 | U33: 1 | V33: 1 | W33: 2 | X33: =IFERROR(MAX(S33:W33),"") -> 2 | Y33: 1 | Z33: =IF(OR(ISBLANK(L33),ISBLANK(l)),"",VLOOKUP(X33-0,'2_Risk_Criteria'!$D$4:$I$9,Y33+1,0)) -> L2 | AA33: ธนพงศ์ เอกพรผดุง
A34: 31 | B34: IT Staff | C34: Personnel | D34: C | E34: ข้อมูลที่พนักงานครอบครอง ข้อมูลถูกเปิดเผยในกรณีที่อุปกรณ์คอมพิวเตอร์สูญหาย เนื่องจากไม่มีการควบคุมการจัดเก็บข้อมูลของพนักงาน | F34: 1.มี CCTV บันทึกเหตุการณ์ | G34: 1 | H34: 1 | I34: 2 | J34: 1 | K34: 2 | L34: =IFERROR(MAX(G34:K34),"") -> 2 | M34: 1 | N34: =IF(ISBLANK(L34),"",VLOOKUP(L34,'2_Risk_Criteria'!$D$4:$I$9,M34+1,0)) -> L2 | O34: =VLOOKUP(N34,'2_Risk_Criteria'!$I$28:$J$42,2,0) -> Accept | P34: 1.มีการตั้ง Screen saver แบบมีรหัสผ่าน ทุก 15 นาที 2.กำหนดพื้นที่ที่มีความสำคัญ 3.ควบคุมการเข้าออกพื้นที่ 4.มีการควบคุมการจัดเก็บข้อมูลที่สำคัญ 5.มีการอบรมความตระหนักความปลอดภัยสารสนเทศ ปีละ 1 ครั้ง 6.Lock หน้าจอเมื่อไม่มีการใช้งาน | S34: 1 | T34: 1 | U34: 2 | V34: 1 | W34: 2 | X34: =IFERROR(MAX(S34:W34),"") -> 2 | Y34: 1 | Z34: =IF(OR(ISBLANK(L34),ISBLANK(l)),"",VLOOKUP(X34-0,'2_Risk_Criteria'!$D$4:$I$9,Y34+1,0)) -> L2 | AA34: ธนพงศ์ เอกพรผดุง
A35: 32 | B35: IT Staff | C35: Personnel | D35: C | E35: พนักงาน เข้าถึงข้อมูลที่สำคัญโดยไม่ได้รับอนุญาต เนื่องจากการจัดการสิทธิการเข้าถึงและการตรวจสอบ ติดตามการใช้งาน | F35: มีการกำหนดสิทธิและการทบทวนสิทธิ | G35: 1 | H35: 1 | I35: 1 | J35: 1 | K35: 1 | L35: =IFERROR(MAX(G35:K35),"") -> 1 | M35: 2 | N35: =IF(ISBLANK(L35),"",VLOOKUP(L35,'2_Risk_Criteria'!$D$4:$I$9,M35+1,0)) -> L2 | O35: =VLOOKUP(N35,'2_Risk_Criteria'!$I$28:$J$42,2,0) -> Accept | P35: มีการกำหนดสิทธิและการทบทวนสิทธิ | S35: 1 | T35: 1 | U35: 1 | V35: 1 | W35: 1 | X35: =IFERROR(MAX(S35:W35),"") -> 1 | Y35: 2 | Z35: =IF(OR(ISBLANK(L35),ISBLANK(l)),"",VLOOKUP(X35-0,'2_Risk_Criteria'!$D$4:$I$9,Y35+1,0)) -> L2 | AA35: ธนพงศ์ เอกพรผดุง
A36: 33 | B36: IT Staff | C36: Personnel | D36: C | E36: พนักงาน ทุจริตนำข้อมูลไปเผยแพร่ เปิดเผย จำหน่าย เนื่องจากไม่มีการคัดกรอง ตรวจสอบประวัติ และการจัดการด้านบุคลากรที่มีประสิทธิผล | F36: ไม่มี | G36: 4 | H36: 3 | I36: 4 | J36: 1 | K36: 3 | L36: =IFERROR(MAX(G36:K36),"") -> 4 | M36: 1 | N36: =IF(ISBLANK(L36),"",VLOOKUP(L36,'2_Risk_Criteria'!$D$4:$I$9,M36+1,0)) -> L4 | O36: =VLOOKUP(N36,'2_Risk_Criteria'!$I$28:$J$42,2,0) -> Accept | P36: ฝ่ายทรัพยากรบุคคล 1.การตรวจสอบประวัติอาชญากรรมของพนักงาน 2.การลงนามสัญญารักษาความลับ (NDA) 3.กำหนดบทลงโทษ เมื่อกระทำการละเมิดข้อตกลงหรือสัญญา 4.การยกเลิกสิทธิการใช้งาน ในกรณีที่พนักงานลาออก หรือ กระทำผิดรายแรง 5.การคืนทรัพย์สินสารสนเทศ ในกรณีที่พนักงานลาออก หรือ กระทำผิดรายแรง 6.ประกาศข้อตกลงและขั้นตอนการปฏิบัติให้ผู้ปฏิบัติงาน รับทราบและปฏิบัติตาม | R36: RTP-002 | S36: 3 | T36: 1 | U36: 3 | V36: 1 | W36: 2 | X36: =IFERROR(MAX(S36:W36),"") -> 3 | Y36: 1 | Z36: =IF(OR(ISBLANK(L36),ISBLANK(l)),"",VLOOKUP(X36-0,'2_Risk_Criteria'!$D$4:$I$9,Y36+1,0)) -> L3 | AA36: ธนพงศ์ เอกพรผดุง
A37: 34 | B37: IT Staff | C37: Personnel | D37: C | E37: พนักงานที่พ้นสภาพ ทุจริตนำข้อมูลไปเผยแพร่ เปิดเผย จำหน่าย เนื่องจากไม่มีการลงนามสัญญารักษาความลับ (NDA) | F37: 1.มีนโยบายควบคุมการเผยแพร่ข้อมูล 2.มีการยกเลิก User เมื่อพนักงานลาออก ในวันสุดท้ายของการทำงานทันที | G37: 4 | H37: 3 | I37: 4 | J37: 1 | K37: 3 | L37: =IFERROR(MAX(G37:K37),"") -> 4 | M37: 1 | N37: =IF(ISBLANK(L37),"",VLOOKUP(L37,'2_Risk_Criteria'!$D$4:$I$9,M37+1,0)) -> L4 | O37: =VLOOKUP(N37,'2_Risk_Criteria'!$I$28:$J$42,2,0) -> Accept | P37: ฝ่ายทรัพยากรบุคคล 1.การตรวจสอบประวัติอาชญากรรมของพนักงาน 2.การลงนามสัญญารักษาความลับ (NDA) 3.กำหนดบทลงโทษ เมื่อกระทำการละเมิดข้อตกลงหรือสัญญา 4.การยกเลิกสิทธิการใช้งาน ในกรณีที่พนักงานลาออก หรือ กระทำผิดรายแรง 5.การคืนทรัพย์สินสารสนเทศ ในกรณีที่พนักงานลาออก หรือ กระทำผิดรายแรง 6.ประกาศข้อตกลงและขั้นตอนการปฏิบัติให้ผู้ปฏิบัติงาน รับทราบและปฏิบัติตาม | R37: RTP-002 | S37: 3 | T37: 1 | U37: 3 | V37: 1 | W37: 2 | X37: =IFERROR(MAX(S37:W37),"") -> 3 | Y37: 1 | Z37: =IF(OR(ISBLANK(L37),ISBLANK(l)),"",VLOOKUP(X37-0,'2_Risk_Criteria'!$D$4:$I$9,Y37+1,0)) -> L3 | AA37: ธนพงศ์ เอกพรผดุง
A38: 35 | B38: User | C38: Personnel | D38: I | E38: พนักงานใหม่ไม่สามารถปฏิบัติงานได้ เนื่องจากไม่มีกระบวนการในการถ่ายทอดความรู้ที่มีประสิทธิผล | F38: 1.ให้ความรู้พนักงานใหม่โดยการสอนระหว่างการปฏิบัติงาน 2.มีการจัดทำคู่มือ | G38: 1 | H38: 1 | I38: 1 | J38: 2 | K38: 3 | L38: =IFERROR(MAX(G38:K38),"") -> 3 | M38: 4 | N38: =IF(ISBLANK(L38),"",VLOOKUP(L38,'2_Risk_Criteria'!$D$4:$I$9,M38+1,0)) -> H12 | O38: =VLOOKUP(N38,'2_Risk_Criteria'!$I$28:$J$42,2,0) -> Transfer | P38: 1.ฝึกอบรมทักษะความรู้ ทุก 6 เดือน 2.ทบทวนเอกสารคู่มือการใช้งาน ทุก 1 ปี 3.ทดสอบความรู้ 4.ส่งพนักงานฝึกอบรมภายนอก เพื่อเพิ่มความรู้ ความสามารถ (Competency) 5.ตั้งตัวชี้วัด KPI เพื่อประเมินหน่วยงาน | S38: 1 | T38: 1 | U38: 1 | V38: 2 | W38: 2 | X38: =IFERROR(MAX(S38:W38),"") -> 2 | Y38: 2 | Z38: =IF(OR(ISBLANK(L38),ISBLANK(l)),"",VLOOKUP(X38-0,'2_Risk_Criteria'!$D$4:$I$9,Y38+1,0)) -> L4 | AA38: ธนพงศ์ เอกพรผดุง
A39: 36 | B39: IT Staff | C39: Personnel | D39: A | E39: ในกรณีที่เกิดเหตุภัยพิบัติฉุกเฉินหรือในขณะที่บริษัทต้องการใช้แผนการดำเนินธุรกิจอย่างต่อเนื่อง อาจไม่มี/ขาดพนักงาน เนื่องจากไม่มีกำหนดรายละเอียดทรัพยากรบุคคลที่จำเป็นในแผนการดำเนินธุรกิจอย่างต่อเนื่อง | F39: 1.มีแผนรับสถานการณ์ฉุกเฉิน | G39: 3 | H39: 4 | I39: 2 | J39: 2 | K39: 2 | L39: =IFERROR(MAX(G39:K39),"") -> 4 | M39: 1 | N39: =IF(ISBLANK(L39),"",VLOOKUP(L39,'2_Risk_Criteria'!$D$4:$I$9,M39+1,0)) -> L4 | O39: =VLOOKUP(N39,'2_Risk_Criteria'!$I$28:$J$42,2,0) -> Accept | P39: 1.จัดทำแบบฟอร์มตารางตรวจเช็คระบบประจำวัน และ แบบฟอร์มตารางตรวจเช็คอุปกรณ์สนับสนุนระบบประจำวัน - ORB-FM-IT-016 : แบบฟอร์มตารางตรวจเช็คระบบประจำวัน - ORB-FM-IT-017 : แบบฟอร์มตารางตรวจเช็คอุปกรณ์สนับสนุนระบบประจำวัน 2.จัดทำแผน และทดสอบแผนรองรับความไม่ต่อเนื่อง (Business Continuity Management) และประชุมสรุปผลการทดสอบ | R39: RTP-003 | S39: 3 | T39: 3 | U39: 2 | V39: 2 | W39: 2 | X39: =IFERROR(MAX(S39:W39),"") -> 3 | Y39: 1 | Z39: =IF(OR(ISBLANK(L39),ISBLANK(l)),"",VLOOKUP(X39-0,'2_Risk_Criteria'!$D$4:$I$9,Y39+1,0)) -> L3 | AA39: ธนพงศ์ เอกพรผดุง
A40: 37 | B40: Room & Location | C40: Facility | D40: C | E40: ผู้ไม่มีสิทธิ เข้าถึงพื้นที่ได้ไม่จำกัด ทำให้ข้อมูลหรืออุปกรณ์ที่มีสำคัญ (Critical) สูญหาย/เสียหาย เนื่องจากไม่มีการกำหนดขอบเขตพื้นที่ความปลอดภัย ความสำคัญ (Critical) | F40: 1.ผู้ให้บริการภายนอก - มีการควบคุมและติดตามเมื่อเข้ามาในพื้นที่ให้บริการ - มีการบันทึก Log การเข้า-ออก Network Rack โซน A (Critical) - มีการควบคุมการเข้าออกโดย Access Control - มีการแจ้งล่วงหน้าก่อนเข้ามาปฏิบัติงาน Network Rack โซน 2.เจ้าหน้าที่ภายใน เฉพาะผู้ได้รับสิทธิหรือผู้ที่ได้รับอนุญาต - ได้รับอนุญาตจากเจ้าหน้าที่ฝ่าย IT 3.ระบบ CCTV บันทึกเหตุการณ์ | G40: 4 | H40: 4 | I40: 2 | J40: 1 | K40: 1 | L40: =IFERROR(MAX(G40:K40),"") -> 4 | M40: 1 | N40: =IF(ISBLANK(L40),"",VLOOKUP(L40,'2_Risk_Criteria'!$D$4:$I$9,M40+1,0)) -> L4 | O40: =VLOOKUP(N40,'2_Risk_Criteria'!$I$28:$J$42,2,0) -> Accept | P40: 1.ให้ปฏิบัติตาม XXX-QP-IT-003 Working in Secure Area (แนวปฏิบัติเกี่ยวกับการปฏิบัติงานในพื้นที่ที่ต้องรักษาความมั่นคงปลอดภัย ) 2.ให้บันทึกตาม XXX-FM-IT-016 แบบฟอร์มตรวจเช็คระบบประจำวัน 3.ให้บันทึกตาม XXX-FM-IT-017 แบบฟอร์มตารางตรวจเช็คอุปกรณ์สนับสนุน 4.ซ้อมแผนไฟไหม้ปีละ 1 ครั้ง ที่จัดขึ้นโดยฝ่ายอาคาร The Trendy Office | R40: RTP-001 | S40: 3 | T40: 3 | U40: 2 | V40: 1 | W40: 1 | X40: =IFERROR(MAX(S40:W40),"") -> 3 | Y40: 1 | Z40: =IF(OR(ISBLANK(L40),ISBLANK(l)),"",VLOOKUP(X40-0,'2_Risk_Criteria'!$D$4:$I$9,Y40+1,0)) -> L3 | AA40: ธนพงศ์ เอกพรผดุง
A41: 38 | B41: Room & Location | C41: Facility | D41: C | E41: ผู้ไม่มีสิทธิ เข้าถึงพื้นที่ได้ไม่จำกัด ทำให้ข้อมูลหรืออุปกรณ์ที่มีสำคัญ (Critical) สูญหาย/เสียหาย เนื่องจากไม่มีการควบคุมการเข้า-ออก | F41: 1.ผู้ให้บริการภายนอก - มีการควบคุมและติดตามเมื่อเข้ามาในพื้นที่ให้บริการ - มีการบันทึก Log การเข้า-ออก Network Rack โซน - มีการควบคุมการเข้าออกโดย Access Control - มีการแจ้งล่วงหน้าก่อนเข้ามาปฏิบัติงาน Network Rack โซน 2.เจ้าหน้าที่ภายใน เฉพาะผู้ได้รับสิทธิหรือผู้ที่ได้รับอนุญาต - ได้รับอนุญาตจากเจ้าหน้าที่ฝ่าย IT 3.ระบบ CCTV บันทึกเหตุการณ์ | G41: 3 | H41: 5 | I41: 3 | J41: 5 | K41: 1 | L41: =IFERROR(MAX(G41:K41),"") -> 5 | M41: 5 | N41: =IF(ISBLANK(L41),"",VLOOKUP(L41,'2_Risk_Criteria'!$D$4:$I$9,M41+1,0)) -> C25 | O41: =VLOOKUP(N41,'2_Risk_Criteria'!$I$28:$J$42,2,0) -> Avoid | P41: 1.ผู้ให้บริการภายนอก - แจ้งชื่อผู้เข้าปฏิบัติงานในพื้นที่ ล่วงหน้าอย่างน้อย 1 วัน ก่อนเข้าปฏิบัติงาน - พิสูจน์ตัวตนของบุคคล เช่น บัตรประจำตัวประชาชน 2.แบ่งพื้นที่ที่รักษาความมั่นคงปลอดภัย 3.ควบคุมการเข้า-ออกพื้นที่ 4.กำหนดผู้มีสิทธิการเข้าถึงพื้นที่ที่รักษาความมั่นคงปลอดภัย (Zone A) 5.ทบทวนผู้มีสิทธิการเข้าถึงพื้นที่ที่รักษาความมั่นคงปลอดภัย (Zone A) ปีละ 1 ครั้ง 6.จัดพื้นที่สำหรับรับ - ส่งของ (Loading Area) ก่อนนำอุปกรณ์หรือสิ่งของเข้าพื้นที่ | S41: 3 | T41: 3 | U41: 2 | V41: 1 | W41: 1 | X41: =IFERROR(MAX(S41:W41),"") -> 3 | Y41: 1 | Z41: =IF(OR(ISBLANK(L41),ISBLANK(l)),"",VLOOKUP(X41-0,'2_Risk_Criteria'!$D$4:$I$9,Y41+1,0)) -> L3 | AA41: ธนพงศ์ เอกพรผดุง
A42: 39 | B42: Room & Location | C42: Facility | D42: I | E42: พื้นที่ไม่สามารถใช้งานได้ หรือไม่ปลอดภัย เนื่องจากขาดการบำรุงรักษาที่ถูกต้อง หรือไม่มีการบำรุงรักษา | F42: 1.มีการทำความสะอาดดูแลโดยฝ่ายอาคาร 2.มีระบบปรับอากาศและมีระบบไฟฟ้าสำรอง ดูแลโดยฝ่ายอาคาร 3.มีระบบไฟฟ้าสำรอง ดูแลโดยฝ่ายสารสนเทศ | G42: 1 | H42: 5 | I42: 1 | J42: 1 | K42: 5 | L42: =IFERROR(MAX(G42:K42),"") -> 5 | M42: 3 | N42: =IF(ISBLANK(L42),"",VLOOKUP(L42,'2_Risk_Criteria'!$D$4:$I$9,M42+1,0)) -> H15 | O42: =VLOOKUP(N42,'2_Risk_Criteria'!$I$28:$J$42,2,0) -> Transfer | P42: ฝ่ายอาคาร 1.กำหนดรอบตรวจสอบระบบปรับอากาศ เดือนละ 1 ครั้ง 2.กำหนดรอบตรวจสอบระบบไฟฟ้าสำรองประจำวัน โดยเจ้าหน้าที่สารสนเทศ 3.กำหนดรอบตรวจสอบระบบไฟฟ้าสำรองทุก 3 เดือน โดยผู้ให้บริการภายนอก 4.กำหนดมีการตรวจสอบระบบท่อน้ำแอร์และท่อน้ำทิ้งแอร์ ทุก 1 เดือน | S42: 1 | T42: 2 | U42: 1 | V42: 1 | W42: 1 | X42: =IFERROR(MAX(S42:W42),"") -> 2 | Y42: 1 | Z42: =IF(OR(ISBLANK(L42),ISBLANK(l)),"",VLOOKUP(X42-0,'2_Risk_Criteria'!$D$4:$I$9,Y42+1,0)) -> L2 | AA42: ธนพงศ์ เอกพรผดุง
A43: 40 | B43: Room & Location | C43: Facility | D43: I | E43: ผู้ไม่มีสิทธิ แก้ไขการตั้งค่าอุปกรณ์ควบคุมสภาพแวดล้อม (อุณหภูมิ และความชื้น) ทำให้ระบบควบคุมทำงานผิดพลาด และระบบภายอุปกรณ์ทำงานผิดปกติ เนื่องจากเนื่องจากไม่มีการควบคุมการเข้า-ออก และการตรวจสอบ ทบทวนสิทธิการเข้าถึง | F43: ไม่มี | G43: 1 | H43: 3 | I43: 2 | J43: 1 | K43: 1 | L43: =IFERROR(MAX(G43:K43),"") -> 3 | M43: 1 | N43: =IF(ISBLANK(L43),"",VLOOKUP(L43,'2_Risk_Criteria'!$D$4:$I$9,M43+1,0)) -> L3 | O43: =VLOOKUP(N43,'2_Risk_Criteria'!$I$28:$J$42,2,0) -> Accept | P43: 1.กำหนดพื้นที่ที่รักษาความมั่นคงปลอดภัย ( Zone A) 2.ควบคุมการเข้า-ออกพื้นที่ 3.กำหนดผู้มีสิทธิการเข้าถึงพื้นที่ที่รักษาความมั่นคงปลอดภัย (Zone A) 4.ทบทวนผู้มีสิทธิการเข้าถึงพื้นที่ที่รักษาความมั่นคงปลอดภัย (Zone A) ปีละ 1 ครั้ง | S43: 1 | T43: 3 | U43: 2 | V43: 1 | W43: 1 | X43: =IFERROR(MAX(S43:W43),"") -> 3 | Y43: 1 | Z43: =IF(OR(ISBLANK(L43),ISBLANK(l)),"",VLOOKUP(X43-0,'2_Risk_Criteria'!$D$4:$I$9,Y43+1,0)) -> L3 | AA43: ธนพงศ์ เอกพรผดุง
A44: 41 | B44: Room & Location | C44: Facility | D44: A | E44: พื้นที่ไม่พร้อมใช้งาน หรือไม่ปลอดภัย เนื่องจากไม่ได้ออกแบบให้สามารถป้องกันความเสียหายจากภัยพิบัติ ธรรมชาติ หรือการก่อการร้าย เช่น ไม่มีการวางระบบป้องกันอัคคีภัย เป็นต้น | F44: 1. มีระบบป้องกันอัคคีภัย 2. มี Smoke Detector 3. มีวางระบบท่อน้ำปรับอากาศ | G44: 3 | H44: 3 | I44: 2 | J44: 1 | K44: 1 | L44: =IFERROR(MAX(G44:K44),"") -> 3 | M44: 1 | N44: =IF(ISBLANK(L44),"",VLOOKUP(L44,'2_Risk_Criteria'!$D$4:$I$9,M44+1,0)) -> L3 | O44: =VLOOKUP(N44,'2_Risk_Criteria'!$I$28:$J$42,2,0) -> Accept | P44: 1. มีระบบป้องกันอัคคีภัย 2. มี Smoke Detector 3. มีวางระบบท่อน้ำปรับอากาศ | S44: 3 | T44: 3 | U44: 2 | V44: 1 | W44: 1 | X44: =IFERROR(MAX(S44:W44),"") -> 3 | Y44: 1 | Z44: =IF(OR(ISBLANK(L44),ISBLANK(l)),"",VLOOKUP(X44-0,'2_Risk_Criteria'!$D$4:$I$9,Y44+1,0)) -> L3 | AA44: ธนพงศ์ เอกพรผดุง
A45: 42 | B45: Room & Location | C45: Facility | D45: A | E45: พื้นที่ Network Rack โซน ไม่เหมาะสมใช้งาน หรือไม่ปลอดภัย เนื่องจากไม่ได้ออกแบบให้สามารถป้องกันความเสียหาย | F45: 1.มีแผนการอกแบบและวางแผนปรับปรุง Network Rack โซน | G45: 4 | H45: 5 | I45: 1 | J45: 1 | K45: 3 | L45: =IFERROR(MAX(G45:K45),"") -> 5 | M45: 1 | N45: =IF(ISBLANK(L45),"",VLOOKUP(L45,'2_Risk_Criteria'!$D$4:$I$9,M45+1,0)) -> M5 | O45: =VLOOKUP(N45,'2_Risk_Criteria'!$I$28:$J$42,2,0) -> Control | P45: 1.วางแผน ออกแบบ และปรับปรุงห้อง Network Rack และอุปกรณ์สนับสนุนระบบ 2.ทดสอบระบบสนับสนุนอุปกรณ์ (Supporting Utility) และติดตามผลการออกแบบปรับปรุง Network Rack โซน และอุปกรณ์สนับสนุนระบบ | R45: RTP-004 | S45: 3 | T45: 3 | U45: 1 | V45: 1 | W45: 2 | X45: =IFERROR(MAX(S45:W45),"") -> 3 | Y45: 1 | Z45: =IF(OR(ISBLANK(L45),ISBLANK(l)),"",VLOOKUP(X45-0,'2_Risk_Criteria'!$D$4:$I$9,Y45+1,0)) -> L3 | AA45: ธนพงศ์ เอกพรผดุง
A46: 43 | B46: Internal Service | C46: Service | D46: I | E46: งานสารสนเทศไม่สามารถให้บริการได้ตามที่ตกลง เนื่องจากเจ้าหน้าที่ผู้เข้าให้บริการไม่มีความรู้ ความชำนาญที่เพียงพอ | F46: 1.ให้ความรู้พนักงานใหม่ 2.จัดทำเอกสารวิธีการปฏิบัติงาน (WI) | G46: 1 | H46: 2 | I46: 1 | J46: 2 | K46: 1 | L46: =IFERROR(MAX(G46:K46),"") -> 2 | M46: 3 | N46: =IF(ISBLANK(L46),"",VLOOKUP(L46,'2_Risk_Criteria'!$D$4:$I$9,M46+1,0)) -> M6 | O46: =VLOOKUP(N46,'2_Risk_Criteria'!$I$28:$J$42,2,0) -> Control | P46: 1.มีฝึกอบรมพนักงาน 2.ส่งพนักงานฝึกอบรมภายนอก เพื่อเพิ่มความรู้ ความสามารถ (Competency) 3.ทบทวนเอกสารคู่มือการปฏิบัติ (WI) ทุก 1 ปี | S46: 1 | T46: 2 | U46: 1 | V46: 2 | W46: 1 | X46: =IFERROR(MAX(S46:W46),"") -> 2 | Y46: 2 | Z46: =IF(OR(ISBLANK(L46),ISBLANK(l)),"",VLOOKUP(X46-0,'2_Risk_Criteria'!$D$4:$I$9,Y46+1,0)) -> L4 | AA46: ธนพงศ์ เอกพรผดุง
...

Sheet 4_RTP
A1: ลำดับ (RTP No.) | C1: มาตรการควบคุมที่เลือก (Selected control) | D1: กิจกรรม (Activity) | E1: ข้อกำหนด (Clause , Annex) | F1: มาตรการ (Control) | G1: Task No. | H1: รายละเอียดสิ่งที่ต้องดำเนินการ (Task Detail) | I1: Task Status | J1: ผู้รับผิดชอบ (Responsibility) | K1: วันที่เริ่ม (Start Date) | L1: วันที่เสร็จสิ้น (Finish Date) | M1: สถานะ (Status) | N1: Progress | O1: 2024 | AU1: 2025 | CQ1: Remark
O2: May | S2: Jun | W2: Jul | AA2: Aug | AE2: Sep | AI2: Oct | AM2: Nov | AQ2: Dec | AU2: Jan | AY2: Feb | BC2: Mar | BG2: Apr | BK2: May | BO2: Jun | BS2: Jul | BW2: Aug | CA2: Sep | CE2: Oct | CI2: Nov | CM2: Dec
O3: 1 | P3: 2 | Q3: 3 | R3: 4 | S3: 1 | T3: 2 | U3: 3 | V3: 4 | W3: 1 | X3: 2 | Y3: 3 | Z3: 4 | AA3: 1 | AB3: 2 | AC3: 3 | AD3: 4 | AE3: 1 | AF3: 2 | AG3: 3 | AH3: 4 | AI3: 1 | AJ3: 2 | AK3: 3 | AL3: 4 | AM3: 1 | AN3: 2 | AO3: 3 | AP3: 4 | AQ3: 1 | AR3: 2 | AS3: 3 | AT3: 4 | AU3: 1 | AV3: 2 | AW3: 3 | AX3: 4 | AY3: 1 | AZ3: 2 | BA3: 3 | BB3: 4 | BC3: 1 | BD3: 2 | BE3: 3 | BF3: 4 | BG3: 1 | BH3: 2 | BI3: 3 | BJ3: 4 | BK3: 1 | BL3: 2 | BM3: 3 | BN3: 4 | BO3: 1 | BP3: 2 | BQ3: 3 | BR3: 4 | BS3: 1 | BT3: 2 | BU3: 3 | BV3: 4 | BW3: 1 | BX3: 2 | BY3: 3 | BZ3: 4 | CA3: 1 | CB3: 2 | CC3: 3 | CD3: 4 | CE3: 1 | CF3: 2 | CG3: 3 | CH3: 4 | CI3: 1 | CJ3: 2 | CK3: 3 | CL3: 4 | CM3: 1 | CN3: 2 | CO3: 3 | CP3: 4
A4: RTP-001 | C4: 1.ให้ปฏิบัติตาม ORB-QP-IT-003 Working in Secure Area (แนวปฏิบัติเกี่ยวกับการปฏิบัติงานในพื้นที่ที่ต้องรักษาความมั่นคงปลอดภัย ) 2.ให้บันทึกตาม ORB-FM-IT-016 แบบฟอร์มตรวจเช็คระบบประจำวัน 3.ให้บันทึกตาม ORB-FM-IT-017 แบบฟอร์มตารางตรวจเช็คอุปกรณ์สนับสนุน 4.ซ้อมแผนไฟไหม้ปีละ 1 ครั้ง ที่จัดขึ้นโดยฝ่ายอาคารPPM SPACE | D4: การป้องกันการเข้าถึงทางกายภาพ | E4: A.7.6 | F4: Working in secure areas การปฏิบัติงานในบริเวณที่ต้องรักษาความมั่นคงปลอดภัย | G4: 1 | H4: ให้ปฏิบัติตาม XXX-QP-IT-003 Working in Secure Area (แนวปฏิบัติเกี่ยวกับการปฏิบัติงานในพื้นที่ที่ต้องรักษาความมั่นคงปลอดภัย ) | I4: Complete
G5: 2 | H5: ให้บันทึกตาม ORB-FM-IT-016 แบบฟอร์มตรวจเช็คระบบประจำวัน | I5: Complete
G6: 3 | H6: ให้บันทึกตาม ORB-FM-IT-017 แบบฟอร์มตารางตรวจเช็คอุปกรณ์สนับสนุน | I6: Complete
G7: 4 | H7: ซ้อมแผนไฟไหม้ปีละ 1 ครั้ง ที่จัดขึ้นโดยฝ่ายอาคาร The Trendy Office | I7: Complete
A8: RTP-002 | C8: ฝ่ายทรัพยากรบุคคล 1. กำหนดให้ผู้ที่จะบรรจุเป็นพนักงาน ต้องมีการตรวจสอบประวัติอาชญากรรม 2. มีการลงนามสัญญารักษาความลับ (NDA) 3. กำหนดบทลงโทษ เมื่อกระทำการละเมิดข้อตกลงหรือสัญญา 4. มีการควบคุมกรณีพนักงานพ้นสภาพให้ยกเลิก รหัสผู้ใช้ภายใน 24 ชั่วโมง ยกเว้นกรณีทำผิดพนักงานพ้นสภาพให้ดำเนินการยกเลิกรหัสผู้ใช้ทันที 5. มีการคืนทรัพย์สินสารสนเทศ ในกรณีที่พนักงานลาออก หรือ กระทำผิดรายแรง 6. มีการประกาศและสื่อสารขั้นตอนการปฏิบัติให้ผู้ปฏิบัติงานที่เกี่ยวข้องรับทราบ | D8: การสร้างความมั่นคงปลอดภัยก่อนการจ้างงาน | E8: A.6.1 | F8: มีมาตรการในการ Screening พนักงาน ลูกจ้าง รวมถึงอาสาสมัคร ที่จะเข้ามาปฏิบัติงานและเข้าถึงสารสนเทศขององค์กร เช่น การตรวจสอบคุณสมบัติ การตรวจสอบประวัติการศึกษา การตรวจสอบประวัติอาชญากรรม | G8: 1 | H8: การตรวจสอบประวัติอาชญากรรมของพนักงาน | I8: Complete
G9: 2 | H9: การลงนามสัญญารักษาความลับ (NDA) | I9: Complete
G10: 3 | H10: กำหนดบทลงโทษ เมื่อกระทำการละเมิดข้อตกลงหรือสัญญา | I10: In Progress
G11: 4 | H11: การยกเลิกสิทธิการใช้งาน ในกรณีที่พนักงานลาออก หรือ กระทำผิดร้ายแรง | I11: Complete
G12: 5 | H12: การคืนทรัพย์สินสารสนเทศ ในกรณีที่พนักงานลาออก หรือ กระทำผิดร้ายแรง | I12: Complete
G13: 6 | H13: ประกาศข้อตกลงและขั้นตอนการปฏิบัติให้ผู้ปฏิบัติงาน รับทราบและปฏิบัติตาม | I13: Complete
A14: RTP-003 | C14: 1. มีระบบ Monitor 2. วางแผนและซ้อมแผนความไม่ต่อเนื่อง (Business Continuity Management) ทุก 1 ปี | D14: ความต่อเนื่องด้านความมั่นคงปลอดภัยสารสนเทศ | E14: A.5.30 | F14: Business Continuity Management Procedure : BCP แนวปฏิบัติการบริหารจัดการความต่อเนื่องทางธุรกิจ | G14: 1 | H14: จัดทำแบบฟอร์มตารางตรวจเช็คระบบประจำวัน และ แบบฟอร์มตารางตรวจเช็คอุปกรณ์สนับสนุนระบบประจำวัน - ORB-FM-IT-016 : แบบฟอร์มตารางตรวจเช็คระบบประจำวัน - ORB-FM-IT-017 : แบบฟอร์มตารางตรวจเช็คอุปกรณ์สนับสนุนระบบประจำวัน | I14: Complete
G15: 2 | H15: จัดทำแผน และทดสอบแผนรองรับความไม่ต่อเนื่อง (Business Continuity Management) และประชุมสรุปผลการทดสอบ | I15: Complete
A16: RTP-004 | C16: 1. วางแผนและออกแบบปรับปรุงห้อง Network Rack และอุปกรณ์สนับสนุนระบบ 2. ควบคุมการติดตั้ง ทดสอบระบบและการใช้งานจริงตามข้อกำหนดที่ตกลงไว้งานที่กำหนด | D16: บริเวณที่ต้องมีการรักษาความมั่นคงปลอดภัย (Secure areas) | E16: A.7.8 | F16: อุปกรณ์ Network ที่มีความสำคัญมีการจัดเก็บไว้ในตู้แร็คที่มีความปลอดภัย ตู้แร็คถูกล็อคเมื่อไม่มีการใช้งาน | G16: 1 | H16: วางแผน ออกแบบ และปรับปรุงห้อง Network Rack และอุปกรณ์สนับสนุนระบบ | I16: Complete
G17: 2 | H17: ทดสอบระบบสนับสนุนอุปกรณ์ (Supporting Utility) และติดตามผลการออกแบบปรับปรุง Network Rack โซน และอุปกรณ์สนับสนุนระบบ | I17: Complete
A18: RTP-005 | C18: 1. มีการกำหนดระดับการให้บริการ (Service Level Agreement : SLA) 2. มีการกำหนด KPI | D18: การสร้างความตระหนัก การให้ความรู้ และการอบรมด้านความมั่นคงปลอดภัยให้แก่พนักงาน | E18: A.6.3 | F18: องค์กรมีการจัดกิจกรรมเพื่อส่งเสริมให้พนักงานมีความตระหนักในเรื่องของการรักษาความมั่นคงปลอดภัยสารสนเทศ | G18: 1 | H18: มีการกำหนดระดับการให้บริการ (Service Level Agreement : SLA) | I18: In Progress
G19: 2 | H19: มีการกำหนด KPI | I19: Complete
A20: RTP-006 | C20: 1. กำหนดนโยบายความมั่นคงปลอดภัยสารสนเทศสำหรับผู้ให้บริการภายนอก จะไม่นำข้อมูลที่สำคัญไปเปิดเผย เผยแพร่ จำหน่าย เป็นต้น 2. กำหนดให้มีการลงนามสัญญารักษาความลับ (NDA) กับผู้ให้บริการภายนอก 3. กำหนดบทลงโทษ เมื่อกระทำการละเมิดข้อตกลงหรือสัญญา 4. อบรมเรื่องความมั่นคงปลอดภัยสารสนเทศให้กับผู้ให้บริการภายนอก เพื่อสร้างความตระหนัก | D20: การระบุความมั่นคงปลอดภัยในข้อตกลงการให้บริการของผู้ให้บริการภายนอก | E20: A.5.20 | F20: การจ้างงานมีการระบุถึงเงื่อนไขในการให้บริการ ได้แก่ สัญญาจ้างงาน และสัญญาตกลงการไม่เปิดเผยข้อมูล (Non - Disclosure Agreement: NDA) ซึ่งระบุถึงการไม่นำความลับขององค์กรไปเปิดเผย โดยผู้ให้บริการภายนอกจะต้องลงนามก่อนการจ้างงาน | G20: 1 | H20: กำหนดนโยบายความปลอดภัยสำหรับผู้ให้บริการภายนอก | I20: Complete
G21: 2 | H21: กำหนดให้มีการลงนามสัญญารักษาความลับ (NDA) กับผู้ให้บริการภายนอก | I21: In Progress
G22: 3 | H22: กำหนดบทลงโทษ เมื่อกระทำการละเมิดข้อตกลงหรือสัญญา | I22: Complete
G23: 4 | H23: อบรมเรื่องความมั่นคงปลอดภัยสารสนเทศให้กับผู้ให้บริการภายนอก เพื่อสร้างความตระหนัก | I23: Complete
A24: RTP-007 | C24: 1. ตรวจสอบและทบทวนสัญญาจ้างของผู้ให้บริการภายนอก 2. จัดทำ List การ MA ของแต่ละบริษัท เพื่อติดตามและตรวจสอบการให้บริการ 3. กำหนดให้ผู้ให้บริการภายนอกแจ้งรายชื่อ และหลักฐานการพิสูจน์ตัวตน เช่น บัตรประจำตัวประชาชน NDA เป็นต้น ก่อนเข้ามาปฏิบัติงานล่วงหน้า ล่วงหน้าอย่างน้อย 1 วัน 4. กรณีมีการเปลี่ยนผู้ปฏิบัติงาน ผู้ให้บริการภายนอกต้องแจ้งผู้ปฏิบัติงานแทน ก่อนเข้าปฏิบัติงาน ล่วงหน้าอย่างน้อย 1 วัน เพื่อตรวจสอบ 5. กำหนดตัวชี้วัดการบริการ (KPI) เพื่อประเมินการให้บริการของผู้ให้บริการภายนอก และนำผลไปพิจารณาการว่าจ้างต่อในครั้งต่อไป | D24: การติดตามและทบทวนบริการของผู้ให้บริการภายนอก | E24: A.5.22 | F24: มีการติดตามและทบทวนการให้บริการของผู้ให้บริการภายนอก เช่น รายงานการดำเนินงานและข้อผิดปกติที่พบ หรือ เอกสารการประเมินผลการบริการ เป็นต้น เพื่อให้มั่นใจว่าได้มีการติดตามการปฏิบัติงานของผู้ให้บริการภายนอกว่าเป็นไปตามข้อตกลงหรือสัญญา รวมถึงมีการประเมินการดำเนินงานของผู้ให้บริการภายนอก และหารือถึงแนวทางพัฒนาการดำเนินงานให้ดียิ่งขึ้น | G24: 1 | H24: ให้บันทึกตาม XXX-FM-IT-031 แบบฟอร์มบันทึกการบริการของผู้ให้บริการภายนอก | I24: Complete
G25: 2 | H25: ให้บันทึกตาม XXX-FM-IT-031 แบบฟอร์มบันทึกการบริการของผู้ให้บริการภายนอก | I25: Complete
G26: 3 | H26: จัดทำขั้นตอนการเข้าปฏิบัติในพื้นที่ ที่รักษาความมั่นคงปลอดภัย XXX-QP-IT-003 : การปฏิบัติงานในพื้นที่ที่ต้องรักษาความมั่นคงปลอดภัย | I26: Complete
G27: 4 | H27: จัดทำขั้นตอนการเข้าปฏิบัติในพื้นที่ ที่รักษาความมั่นคงปลอดภัย XXX-QP-IT-003 : การปฏิบัติงานในพื้นที่ที่ต้องรักษาความมั่นคงปลอดภัย | I27: Complete
G28: 5 | H28: จัดทำตัวชี้วัดการบริการ (KPI) เพื่อประเมินการให้บริการของผู้ให้บริการภายนอก | I28: In Progress

Sheet Type of Asset
A1: NO | B1: Type of Asset | C1: การจำแนกประเภททรัพย์สิน | D1: ตัวอย่าง
A2: 1 | B2: ฮาร์ดแวร์ (Hardware) | C2: - อุปกรณ์ประมวลหลัก - อุปกรณ์ต่อพ่วงระบบคอมพิวเตอร์ - อุปกรณ์สนับสนุน | D2: - เครื่องคอมพิวเตอร์ - เครื่องสำรองไฟ (UPS) - อุปกรณ์ดับเพลิง - อุปกรณ์ตรวจสอบเพลิงไหม้
A3: 2 | B3: ซอฟต์แวร์ (Software) | C3: - ระบบปฏิบัติการ - ซอฟต์แวร์สนับสนุนที่ใช้ในการบริหารจัดการ - ซอฟต์แวร์สำเร็จรูป - ซอฟต์แวร์สนับสนุนงานทางธุรกิจ - Free Software | D3: - Microsoft Windows - MacOS - Google Workspace - Microsoft Office - Jamf Pro - AnyDesk - Slack - Jira Software - Express
A4: 3 | B4: ข้อมูลและสารสนเทศ (Data and Information) | C4: - ข้อมูลรูปแบบกระดาษ - ข้อมูลรูปแบบอิเล็กทรอนิกส์ | D4: - ข้อมูลบัญชีการเงิน - ข้อมูลบุคลากร - Network Diagram - ข้อมูลการตั้งค่าในระบบ - ข้อมูลสารสนเทศ - สัญญารักษาความลับ - สัญญาจ้างงาน - สัญญาจ้างเหมาบริการ
A5: 4 | B5: เครือข่าย (Network) | C5: - อุปกรณ์เครือข่าย - สื่อสัญญาณ - เครือข่ายเชื่อมต่อการสื่อสาร | D5: - Network switch - Network Controller - Firewall - Access Point
A6: 5 | B6: บุคลากร (Personnel) | C6: - Assistant IT Support Manager - IT Support | D6: - ผู้ดูแลระบบ (Assistant IT Support Manager) - เจ้าหน้าที่ดูแลระบบงาน (IT Support) - User
A7: 6 | B7: อาคาร สถานที่ (Facility) | C7: - อาคาร สถานที่ตั้ง - ห้องหรือสถานที่ปฏิบัติงาน | D7: - Network Rack - IT โซน - ห้องประชุม
A8: 7 | B8: บริการ (Service) | C8: - บริการที่สนับสนุนการปฏิบัติงานภายในบริษัทฯ - บริการที่ได้รับจากผู้ให้บริการภายนอกบริษัทฯ | D8: - ระบบคลาวด์ (Cloud Service) - บริการแก้ไขปัญหาระบบ - บริการดูแลระบบ

Sheet Group Of Asset
A1: No. | B1: Type of Asset | C1: Group of Asset | D1: ตัวอย่าง
A2: 1 | B2: Hardware | C2: Hardware | D2: Computer
D3: Notebook
D4: NAS
C5: Supporting Utility | D5: UPS
D6: CCTV
D7: Fire System
D8: Air condition System
A9: 2 | B9: Software | C9: Operating System | D9: MacOS
D10: Windows 10
C11: Business Application | D11: Google Workspace
D12: Express
D13: Zimbra mail
D14: Onebox
C15: Software Package | D15: Microsoft Office 365
D16: devert
D17: GitHub
D18: Data gip
C19: Supporting Software
C20: Freeware | D20: Python
D21: Pycharm
D22: Fox-pro
D23: Anydesk
D24: Visual Studio Code
D25: Microsoft Remote Desktop
A26: 3 | B26: Data and Information | C26: Paper Document | D26: ข้อมูลบัญชีการเงิน
D27: สัญญารักษาความลับ
D28: สัญญาจ้างงาน
D29: ข้อมูลบุคลากร
D30: สัญญาจ้างเหมาบริการ
D31: เอกสารประกอบการ Training ระบบ TigerSoft
C32: Electronic File | D32: ข้อมูลการตั้งค่าในระบบ
D33: Network Diagram
D34: Work instruction สำหรับฝ่ายสารสนเทศ
D35: Source Code
D36: Test Case
D37: Bugs / Defects
A38: 4 | B38: Network | C38: Network Device | D38: Core Switch
D39: Cloud Key
D40: Routers and Wireless
...

Sheet Pivot Table
A1: COUNTA of ทางเลือกการตอบสนองต่อความเสี่ยง (Risk Response Option) | B1: ทางเลือกการตอบสนองต่อความเสี่ยง (Risk Response Option)
A2: ประเภททรัพย์สิน (Type) | B2: Accepting | C2: Controlling | D2: Transfer | E2: Grand Total
A3: Data and Information | B3: 2 | C3: 0 | D3: 0 | E3: 2
A4: Facility | B4: 4 | C4: 2 | D4: 0 | E4: 6
A5: Hardware | B5: 3 | C5: 3 | D5: 0 | E5: 6
A6: Network | B6: 13 | C6: 3 | D6: 0 | E6: 16
A7: Personnel | B7: 2 | C7: 2 | D7: 2 | E7: 6
A8: Service | B8: 4 | C8: 14 | D8: 0 | E8: 18
A9: Software | B9: 11 | C9: 1 | D9: 0 | E9: 12
A10: Grand Total | B10: 39 | C10: 25 | D10: 2 | E10: 66

Sheet Data Support
A2: ประเภททรัพย์สิน (Type) | B2: Accepting | C2: Controlling | D2: Transfer | E2: Avoid | F2: Grand Total
A3: Data and Information | B3: =VLOOKUP($A$3:$A$10,'Pivot Table'!$A$3:$E$10,2,FALSE) -> 2 | C3: 0 | D3: 0 | E3: 0 | F3: 2
A4: Facility | B4: =VLOOKUP($A$3:$A$10,'Pivot Table'!$A$3:$E$10,2,FALSE) -> 4 | C4: =VLOOKUP($A$3:$A$10,'Pivot Table'!$A$3:$E$10,3,FALSE) -> 2 | D4: 0 | E4: 0 | F4: 6
A5: Hardware | B5: =VLOOKUP($A$3:$A$10,'Pivot Table'!$A$3:$E$10,2,FALSE) -> 3 | C5: =VLOOKUP($A$3:$A$10,'Pivot Table'!$A$3:$E$10,3,FALSE) -> 3 | D5: 0 | E5: 0 | F5: 6
A6: Network | B6: =VLOOKUP($A$3:$A$10,'Pivot Table'!$A$3:$E$10,2,FALSE) -> 13 | C6: =VLOOKUP($A$3:$A$10,'Pivot Table'!$A$3:$E$10,3,FALSE) -> 3 | D6: 0 | E6: 0 | F6: 16
A7: Personnel | B7: =VLOOKUP($A$3:$A$10,'Pivot Table'!$A$3:$E$10,2,FALSE) -> 2 | C7: =VLOOKUP($A$3:$A$10,'Pivot Table'!$A$3:$E$10,3,FALSE) -> 2 | D7: =VLOOKUP($A$3:$A$10,'Pivot Table'!$A$3:$E$10,4,FALSE) -> 2 | E7: 0 | F7: 6
A8: Service | B8: =VLOOKUP($A$3:$A$10,'Pivot Table'!$A$3:$E$10,2,FALSE) -> 4 | C8: =VLOOKUP($A$3:$A$10,'Pivot Table'!$A$3:$E$10,3,FALSE) -> 14 | D8: 0 | E8: 0 | F8: 18
A9: Software | B9: =VLOOKUP($A$3:$A$10,'Pivot Table'!$A$3:$E$10,2,FALSE) -> 11 | C9: =VLOOKUP($A$3:$A$10,'Pivot Table'!$A$3:$E$10,3,FALSE) -> 1 | D9: 0 | E9: 0 | F9: 12
A10: Grand Total | B10: =VLOOKUP($A$3:$A$10,'Pivot Table'!$A$3:$E$10,2,FALSE) -> 39 | C10: =VLOOKUP($A$3:$A$10,'Pivot Table'!$A$3:$E$10,3,FALSE) -> 25 | D10: =VLOOKUP($A$3:$A$10,'Pivot Table'!$A$3:$E$10,4,FALSE) -> 2 | E10: 0 | F10: 66
